Workbook

Sheet 時間編集
A1: シフト表 - 時間編集シート
A2: ※ 各スタッフの「開始時刻」「終了時刻」「中抜け開始」「中抜け終了」を入力してください（例: 9:00）
A3: スタッフ | B3: 曜日 | C3: 開始時刻 | D3: 終了時刻 | E3: 中抜け開始 | F3: 中抜け終了 | G3: 実働時間（自動計算）
A4: 石渡 | B4: 月 | G4: =IF(AND(D4<>"",C4<>""),(D4-C4)-IF(AND(F4<>"",E4<>""),F4-E4,0),"")
B5: 火 | G5: =IF(AND(D5<>"",C5<>""),(D5-C5)-IF(AND(F5<>"",E5<>""),F5-E5,0),"")
B6: 水 | G6: =IF(AND(D6<>"",C6<>""),(D6-C6)-IF(AND(F6<>"",E6<>""),F6-E6,0),"")
B7: 木 | G7: =IF(AND(D7<>"",C7<>""),(D7-C7)-IF(AND(F7<>"",E7<>""),F7-E7,0),"")
B8: 金 | G8: =IF(AND(D8<>"",C8<>""),(D8-C8)-IF(AND(F8<>"",E8<>""),F8-E8,0),"")
B9: 土 | G9: =IF(AND(D9<>"",C9<>""),(D9-C9)-IF(AND(F9<>"",E9<>""),F9-E9,0),"")
B10: 日 | G10: =IF(AND(D10<>"",C10<>""),(D10-C10)-IF(AND(F10<>"",E10<>""),F10-E10,0),"")
A11: 小泉 | B11: 月 | G11: =IF(AND(D11<>"",C11<>""),(D11-C11)-IF(AND(F11<>"",E11<>""),F11-E11,0),"")
B12: 火 | G12: =IF(AND(D12<>"",C12<>""),(D12-C12)-IF(AND(F12<>"",E12<>""),F12-E12,0),"")
B13: 水 | G13: =IF(AND(D13<>"",C13<>""),(D13-C13)-IF(AND(F13<>"",E13<>""),F13-E13,0),"")
B14: 木 | G14: =IF(AND(D14<>"",C14<>""),(D14-C14)-IF(AND(F14<>"",E14<>""),F14-E14,0),"")
B15: 金 | G15: =IF(AND(D15<>"",C15<>""),(D15-C15)-IF(AND(F15<>"",E15<>""),F15-E15,0),"")
B16: 土 | G16: =IF(AND(D16<>"",C16<>""),(D16-C16)-IF(AND(F16<>"",E16<>""),F16-E16,0),"")
B17: 日 | G17: =IF(AND(D17<>"",C17<>""),(D17-C17)-IF(AND(F17<>"",E17<>""),F17-E17,0),"")
A18: 伊藤 | B18: 月 | G18: =IF(AND(D18<>"",C18<>""),(D18-C18)-IF(AND(F18<>"",E18<>""),F18-E18,0),"")
B19: 火 | G19: =IF(AND(D19<>"",C19<>""),(D19-C19)-IF(AND(F19<>"",E19<>""),F19-E19,0),"")
B20: 水 | G20: =IF(AND(D20<>"",C20<>""),(D20-C20)-IF(AND(F20<>"",E20<>""),F20-E20,0),"")
B21: 木 | G21: =IF(AND(D21<>"",C21<>""),(D21-C21)-IF(AND(F21<>"",E21<>""),F21-E21,0),"")
B22: 金 | G22: =IF(AND(D22<>"",C22<>""),(D22-C22)-IF(AND(F22<>"",E22<>""),F22-E22,0),"")
B23: 土 | G23: =IF(AND(D23<>"",C23<>""),(D23-C23)-IF(AND(F23<>"",E23<>""),F23-E23,0),"")
B24: 日 | G24: =IF(AND(D24<>"",C24<>""),(D24-C24)-IF(AND(F24<>"",E24<>""),F24-E24,0),"")

Sheet ビジュアライズ
A1: シフト表 - ビジュアライズ
A2: ※ 時間編集シートに入力した内容が自動反映されます。勤務時間帯はオレンジ、中抜けはグレーで表示されます。
A3: スタッフ | B3: 曜日 | C3: 8:00 | D3: 8:30 | E3: 9:00 | F3: 9:30 | G3: 10:00 | H3: 10:30 | I3: 11:00 | J3: 11:30 | K3: 12:00 | L3: 12:30 | M3: 13:00 | N3: 13:30 | O3: 14:00 | P3: 14:30 | Q3: 15:00 | R3: 15:30 | S3: 16:00 | T3: 16:30 | U3: 17:00 | V3: 17:30 | W3: 18:00 | X3: 18:30 | Y3: 19:00
A4: 石渡 | B4: 月 | C4: =IF(AND(時間編集!C4<>"",時間編集!D4<>""),IF(AND(時間編集!E4<>"",時間編集!F4<>"",時間編集!E4<=0.3333333333333333,時間編集!F4>=0.3541666666666667),"中抜",IF(AND(時間編集!C4<=0.3333333333333333,時間編集!D4>=0.3541666666666667),"●","")),"") | D4: =IF(AND(時間編集!C4<>"",時間編集!D4<>""),IF(AND(時間編集!E4<>"",時間編集!F4<>"",時間編集!E4<=0.3541666666666667,時間編集!F4>=0.375),"中抜",IF(AND(時間編集!C4<=0.3541666666666667,時間編集!D4>=0.375),"●","")),"") | E4: =IF(AND(時間編集!C4<>"",時間編集!D4<>""),IF(AND(時間編集!E4<>"",時間編集!F4<>"",時間編集!E4<=0.375,時間編集!F4>=0.3958333333333333),"中抜",IF(AND(時間編集!C4<=0.375,時間編集!D4>=0.3958333333333333),"●","")),"") | F4: =IF(AND(時間編集!C4<>"",時間編集!D4<>""),IF(AND(時間編集!E4<>"",時間編集!F4<>"",時間編集!E4<=0.3958333333333333,時間編集!F4>=0.4166666666666667),"中抜",IF(AND(時間編集!C4<=0.3958333333333333,時間編集!D4>=0.4166666666666667),"●","")),"") | G4: =IF(AND(時間編集!C4<>"",時間編集!D4<>""),IF(AND(時間編集!E4<>"",時間編集!F4<>"",時間編集!E4<=0.4166666666666667,時間編集!F4>=0.4375),"中抜",IF(AND(時間編集!C4<=0.4166666666666667,時間編集!D4>=0.4375),"●","")),"") | H4: =IF(AND(時間編集!C4<>"",時間編集!D4<>""),IF(AND(時間編集!E4<>"",時間編集!F4<>"",時間編集!E4<=0.4375,時間編集!F4>=0.4583333333333333),"中抜",IF(AND(時間編集!C4<=0.4375,時間編集!D4>=0.4583333333333333),"●","")),"") | I4: =IF(AND(時間編集!C4<>"",時間編集!D4<>""),IF(AND(時間編集!E4<>"",時間編集!F4<>"",時間編集!E4<=0.4583333333333333,時間編集!F4>=0.4791666666666667),"中抜",IF(AND(時間編集!C4<=0.4583333333333333,時間編集!D4>=0.4791666666666667),"●","")),"") | J4: =IF(AND(時間編集!C4<>"",時間編集!D4<>""),IF(AND(時間編集!E4<>"",時間編集!F4<>"",時間編集!E4<=0.4791666666666667,時間編集!F4>=0.5),"中抜",IF(AND(時間編集!C4<=0.4791666666666667,時間編集!D4>=0.5),"●","")),"") | K4: =IF(AND(時間編集!C4<>"",時間編集!D4<>""),IF(AND(時間編集!E4<>"",時間編集!F4<>"",時間編集!E4<=0.5,時間編集!F4>=0.5208333333333334),"中抜",IF(AND(時間編集!C4<=0.5,時間編集!D4>=0.5208333333333334),"●","")),"") | L4: =IF(AND(時間編集!C4<>"",時間編集!D4<>""),IF(AND(時間編集!E4<>"",時間編集!F4<>"",時間編集!E4<=0.5208333333333334,時間編集!F4>=0.5416666666666666),"中抜",IF(AND(時間編集!C4<=0.5208333333333334,時間編集!D4>=0.5416666666666666),"●","")),"") | M4: =IF(AND(時間編集!C4<>"",時間編集!D4<>""),IF(AND(時間編集!E4<>"",時間編集!F4<>"",時間編集!E4<=0.5416666666666666,時間編集!F4>=0.5625),"中抜",IF(AND(時間編集!C4<=0.5416666666666666,時間編集!D4>=0.5625),"●","")),"") | N4: =IF(AND(時間編集!C4<>"",時間編集!D4<>""),IF(AND(時間編集!E4<>"",時間編集!F4<>"",時間編集!E4<=0.5625,時間編集!F4>=0.5833333333333334),"中抜",IF(AND(時間編集!C4<=0.5625,時間編集!D4>=0.5833333333333334),"●","")),"") | O4: =IF(AND(時間編集!C4<>"",時間編集!D4<>""),IF(AND(時間編集!E4<>"",時間編集!F4<>"",時間編集!E4<=0.5833333333333334,時間編集!F4>=0.6041666666666666),"中抜",IF(AND(時間編集!C4<=0.5833333333333334,時間編集!D4>=0.6041666666666666),"●","")),"") | P4: =IF(AND(時間編集!C4<>"",時間編集!D4<>""),IF(AND(時間編集!E4<>"",時間編集!F4<>"",時間編集!E4<=0.6041666666666666,時間編集!F4>=0.625),"中抜",IF(AND(時間編集!C4<=0.6041666666666666,時間編集!D4>=0.625),"●","")),"") | Q4: =IF(AND(時間編集!C4<>"",時間編集!D4<>""),IF(AND(時間編集!E4<>"",時間編集!F4<>"",時間編集!E4<=0.625,時間編集!F4>=0.6458333333333334),"中抜",IF(AND(時間編集!C4<=0.625,時間編集!D4>=0.6458333333333334),"●","")),"") | R4: =IF(AND(時間編集!C4<>"",時間編集!D4<>""),IF(AND(時間編集!E4<>"",時間編集!F4<>"",時間編集!E4<=0.6458333333333334,時間編集!F4>=0.6666666666666666),"中抜",IF(AND(時間編集!C4<=0.6458333333333334,時間編集!D4>=0.6666666666666666),"●","")),"") | S4: =IF(AND(時間編集!C4<>"",時間編集!D4<>""),IF(AND(時間編集!E4<>"",時間編集!F4<>"",時間編集!E4<=0.6666666666666666,時間編集!F4>=0.6875),"中抜",IF(AND(時間編集!C4<=0.6666666666666666,時間編集!D4>=0.6875),"●","")),"") | T4: =IF(AND(時間編集!C4<>"",時間編集!D4<>""),IF(AND(時間編集!E4<>"",時間編集!F4<>"",時間編集!E4<=0.6875,時間編集!F4>=0.7083333333333334),"中抜",IF(AND(時間編集!C4<=0.6875,時間編集!D4>=0.7083333333333334),"●","")),"") | U4: =IF(AND(時間編集!C4<>"",時間編集!D4<>""),IF(AND(時間編集!E4<>"",時間編集!F4<>"",時間編集!E4<=0.7083333333333334,時間編集!F4>=0.7291666666666666),"中抜",IF(AND(時間編集!C4<=0.7083333333333334,時間編集!D4>=0.7291666666666666),"●","")),"") | V4: =IF(AND(時間編集!C4<>"",時間編集!D4<>""),IF(AND(時間編集!E4<>"",時間編集!F4<>"",時間編集!E4<=0.7291666666666666,時間編集!F4>=0.75),"中抜",IF(AND(時間編集!C4<=0.7291666666666666,時間編集!D4>=0.75),"●","")),"") | W4: =IF(AND(時間編集!C4<>"",時間編集!D4<>""),IF(AND(時間編集!E4<>"",時間編集!F4<>"",時間編集!E4<=0.75,時間編集!F4>=0.7708333333333334),"中抜",IF(AND(時間編集!C4<=0.75,時間編集!D4>=0.7708333333333334),"●","")),"") | X4: =IF(AND(時間編集!C4<>"",時間編集!D4<>""),IF(AND(時間編集!E4<>"",時間編集!F4<>"",時間編集!E4<=0.7708333333333334,時間編集!F4>=0.7916666666666666),"中抜",IF(AND(時間編集!C4<=0.7708333333333334,時間編集!D4>=0.7916666666666666),"●","")),"")
B5: 火 | C5: =IF(AND(時間編集!C5<>"",時間編集!D5<>""),IF(AND(時間編集!E5<>"",時間編集!F5<>"",時間編集!E5<=0.3333333333333333,時間編集!F5>=0.3541666666666667),"中抜",IF(AND(時間編集!C5<=0.3333333333333333,時間編集!D5>=0.3541666666666667),"●","")),"") | D5: =IF(AND(時間編集!C5<>"",時間編集!D5<>""),IF(AND(時間編集!E5<>"",時間編集!F5<>"",時間編集!E5<=0.3541666666666667,時間編集!F5>=0.375),"中抜",IF(AND(時間編集!C5<=0.3541666666666667,時間編集!D5>=0.375),"●","")),"") | E5: =IF(AND(時間編集!C5<>"",時間編集!D5<>""),IF(AND(時間編集!E5<>"",時間編集!F5<>"",時間編集!E5<=0.375,時間編集!F5>=0.3958333333333333),"中抜",IF(AND(時間編集!C5<=0.375,時間編集!D5>=0.3958333333333333),"●","")),"") | F5: =IF(AND(時間編集!C5<>"",時間編集!D5<>""),IF(AND(時間編集!E5<>"",時間編集!F5<>"",時間編集!E5<=0.3958333333333333,時間編集!F5>=0.4166666666666667),"中抜",IF(AND(時間編集!C5<=0.3958333333333333,時間編集!D5>=0.4166666666666667),"●","")),"") | G5: =IF(AND(時間編集!C5<>"",時間編集!D5<>""),IF(AND(時間編集!E5<>"",時間編集!F5<>"",時間編集!E5<=0.4166666666666667,時間編集!F5>=0.4375),"中抜",IF(AND(時間編集!C5<=0.4166666666666667,時間編集!D5>=0.4375),"●","")),"") | H5: =IF(AND(時間編集!C5<>"",時間編集!D5<>""),IF(AND(時間編集!E5<>"",時間編集!F5<>"",時間編集!E5<=0.4375,時間編集!F5>=0.4583333333333333),"中抜",IF(AND(時間編集!C5<=0.4375,時間編集!D5>=0.4583333333333333),"●","")),"") | I5: =IF(AND(時間編集!C5<>"",時間編集!D5<>""),IF(AND(時間編集!E5<>"",時間編集!F5<>"",時間編集!E5<=0.4583333333333333,時間編集!F5>=0.4791666666666667),"中抜",IF(AND(時間編集!C5<=0.4583333333333333,時間編集!D5>=0.4791666666666667),"●","")),"") | J5: =IF(AND(時間編集!C5<>"",時間編集!D5<>""),IF(AND(時間編集!E5<>"",時間編集!F5<>"",時間編集!E5<=0.4791666666666667,時間編集!F5>=0.5),"中抜",IF(AND(時間編集!C5<=0.4791666666666667,時間編集!D5>=0.5),"●","")),"") | K5: =IF(AND(時間編集!C5<>"",時間編集!D5<>""),IF(AND(時間編集!E5<>"",時間編集!F5<>"",時間編集!E5<=0.5,時間編集!F5>=0.5208333333333334),"中抜",IF(AND(時間編集!C5<=0.5,時間編集!D5>=0.5208333333333334),"●","")),"") | L5: =IF(AND(時間編集!C5<>"",時間編集!D5<>""),IF(AND(時間編集!E5<>"",時間編集!F5<>"",時間編集!E5<=0.5208333333333334,時間編集!F5>=0.5416666666666666),"中抜",IF(AND(時間編集!C5<=0.5208333333333334,時間編集!D5>=0.5416666666666666),"●","")),"") | M5: =IF(AND(時間編集!C5<>"",時間編集!D5<>""),IF(AND(時間編集!E5<>"",時間編集!F5<>"",時間編集!E5<=0.5416666666666666,時間編集!F5>=0.5625),"中抜",IF(AND(時間編集!C5<=0.5416666666666666,時間編集!D5>=0.5625),"●","")),"") | N5: =IF(AND(時間編集!C5<>"",時間編集!D5<>""),IF(AND(時間編集!E5<>"",時間編集!F5<>"",時間編集!E5<=0.5625,時間編集!F5>=0.5833333333333334),"中抜",IF(AND(時間編集!C5<=0.5625,時間編集!D5>=0.5833333333333334),"●","")),"") | O5: =IF(AND(時間編集!C5<>"",時間編集!D5<>""),IF(AND(時間編集!E5<>"",時間編集!F5<>"",時間編集!E5<=0.5833333333333334,時間編集!F5>=0.6041666666666666),"中抜",IF(AND(時間編集!C5<=0.5833333333333334,時間編集!D5>=0.6041666666666666),"●","")),"") | P5: =IF(AND(時間編集!C5<>"",時間編集!D5<>""),IF(AND(時間編集!E5<>"",時間編集!F5<>"",時間編集!E5<=0.6041666666666666,時間編集!F5>=0.625),"中抜",IF(AND(時間編集!C5<=0.6041666666666666,時間編集!D5>=0.625),"●","")),"") | Q5: =IF(AND(時間編集!C5<>"",時間編集!D5<>""),IF(AND(時間編集!E5<>"",時間編集!F5<>"",時間編集!E5<=0.625,時間編集!F5>=0.6458333333333334),"中抜",IF(AND(時間編集!C5<=0.625,時間編集!D5>=0.6458333333333334),"●","")),"") | R5: =IF(AND(時間編集!C5<>"",時間編集!D5<>""),IF(AND(時間編集!E5<>"",時間編集!F5<>"",時間編集!E5<=0.6458333333333334,時間編集!F5>=0.6666666666666666),"中抜",IF(AND(時間編集!C5<=0.6458333333333334,時間編集!D5>=0.6666666666666666),"●","")),"") | S5: =IF(AND(時間編集!C5<>"",時間編集!D5<>""),IF(AND(時間編集!E5<>"",時間編集!F5<>"",時間編集!E5<=0.6666666666666666,時間編集!F5>=0.6875),"中抜",IF(AND(時間編集!C5<=0.6666666666666666,時間編集!D5>=0.6875),"●","")),"") | T5: =IF(AND(時間編集!C5<>"",時間編集!D5<>""),IF(AND(時間編集!E5<>"",時間編集!F5<>"",時間編集!E5<=0.6875,時間編集!F5>=0.7083333333333334),"中抜",IF(AND(時間編集!C5<=0.6875,時間編集!D5>=0.7083333333333334),"●","")),"") | U5: =IF(AND(時間編集!C5<>"",時間編集!D5<>""),IF(AND(時間編集!E5<>"",時間編集!F5<>"",時間編集!E5<=0.7083333333333334,時間編集!F5>=0.7291666666666666),"中抜",IF(AND(時間編集!C5<=0.7083333333333334,時間編集!D5>=0.7291666666666666),"●","")),"") | V5: =IF(AND(時間編集!C5<>"",時間編集!D5<>""),IF(AND(時間編集!E5<>"",時間編集!F5<>"",時間編集!E5<=0.7291666666666666,時間編集!F5>=0.75),"中抜",IF(AND(時間編集!C5<=0.7291666666666666,時間編集!D5>=0.75),"●","")),"") | W5: =IF(AND(時間編集!C5<>"",時間編集!D5<>""),IF(AND(時間編集!E5<>"",時間編集!F5<>"",時間編集!E5<=0.75,時間編集!F5>=0.7708333333333334),"中抜",IF(AND(時間編集!C5<=0.75,時間編集!D5>=0.7708333333333334),"●","")),"") | X5: =IF(AND(時間編集!C5<>"",時間編集!D5<>""),IF(AND(時間編集!E5<>"",時間編集!F5<>"",時間編集!E5<=0.7708333333333334,時間編集!F5>=0.7916666666666666),"中抜",IF(AND(時間編集!C5<=0.7708333333333334,時間編集!D5>=0.7916666666666666),"●","")),"")
B6: 水 | C6: =IF(AND(時間編集!C6<>"",時間編集!D6<>""),IF(AND(時間編集!E6<>"",時間編集!F6<>"",時間編集!E6<=0.3333333333333333,時間編集!F6>=0.3541666666666667),"中抜",IF(AND(時間編集!C6<=0.3333333333333333,時間編集!D6>=0.3541666666666667),"●","")),"") | D6: =IF(AND(時間編集!C6<>"",時間編集!D6<>""),IF(AND(時間編集!E6<>"",時間編集!F6<>"",時間編集!E6<=0.3541666666666667,時間編集!F6>=0.375),"中抜",IF(AND(時間編集!C6<=0.3541666666666667,時間編集!D6>=0.375),"●","")),"") | E6: =IF(AND(時間編集!C6<>"",時間編集!D6<>""),IF(AND(時間編集!E6<>"",時間編集!F6<>"",時間編集!E6<=0.375,時間編集!F6>=0.3958333333333333),"中抜",IF(AND(時間編集!C6<=0.375,時間編集!D6>=0.3958333333333333),"●","")),"") | F6: =IF(AND(時間編集!C6<>"",時間編集!D6<>""),IF(AND(時間編集!E6<>"",時間編集!F6<>"",時間編集!E6<=0.3958333333333333,時間編集!F6>=0.4166666666666667),"中抜",IF(AND(時間編集!C6<=0.3958333333333333,時間編集!D6>=0.4166666666666667),"●","")),"") | G6: =IF(AND(時間編集!C6<>"",時間編集!D6<>""),IF(AND(時間編集!E6<>"",時間編集!F6<>"",時間編集!E6<=0.4166666666666667,時間編集!F6>=0.4375),"中抜",IF(AND(時間編集!C6<=0.4166666666666667,時間編集!D6>=0.4375),"●","")),"") | H6: =IF(AND(時間編集!C6<>"",時間編集!D6<>""),IF(AND(時間編集!E6<>"",時間編集!F6<>"",時間編集!E6<=0.4375,時間編集!F6>=0.4583333333333333),"中抜",IF(AND(時間編集!C6<=0.4375,時間編集!D6>=0.4583333333333333),"●","")),"") | I6: =IF(AND(時間編集!C6<>"",時間編集!D6<>""),IF(AND(時間編集!E6<>"",時間編集!F6<>"",時間編集!E6<=0.4583333333333333,時間編集!F6>=0.4791666666666667),"中抜",IF(AND(時間編集!C6<=0.4583333333333333,時間編集!D6>=0.4791666666666667),"●","")),"") | J6: =IF(AND(時間編集!C6<>"",時間編集!D6<>""),IF(AND(時間編集!E6<>"",時間編集!F6<>"",時間編集!E6<=0.4791666666666667,時間編集!F6>=0.5),"中抜",IF(AND(時間編集!C6<=0.4791666666666667,時間編集!D6>=0.5),"●","")),"") | K6: =IF(AND(時間編集!C6<>"",時間編集!D6<>""),IF(AND(時間編集!E6<>"",時間編集!F6<>"",時間編集!E6<=0.5,時間編集!F6>=0.5208333333333334),"中抜",IF(AND(時間編集!C6<=0.5,時間編集!D6>=0.5208333333333334),"●","")),"") | L6: =IF(AND(時間編集!C6<>"",時間編集!D6<>""),IF(AND(時間編集!E6<>"",時間編集!F6<>"",時間編集!E6<=0.5208333333333334,時間編集!F6>=0.5416666666666666),"中抜",IF(AND(時間編集!C6<=0.5208333333333334,時間編集!D6>=0.5416666666666666),"●","")),"") | M6: =IF(AND(時間編集!C6<>"",時間編集!D6<>""),IF(AND(時間編集!E6<>"",時間編集!F6<>"",時間編集!E6<=0.5416666666666666,時間編集!F6>=0.5625),"中抜",IF(AND(時間編集!C6<=0.5416666666666666,時間編集!D6>=0.5625),"●","")),"") | N6: =IF(AND(時間編集!C6<>"",時間編集!D6<>""),IF(AND(時間編集!E6<>"",時間編集!F6<>"",時間編集!E6<=0.5625,時間編集!F6>=0.5833333333333334),"中抜",IF(AND(時間編集!C6<=0.5625,時間編集!D6>=0.5833333333333334),"●","")),"") | O6: =IF(AND(時間編集!C6<>"",時間編集!D6<>""),IF(AND(時間編集!E6<>"",時間編集!F6<>"",時間編集!E6<=0.5833333333333334,時間編集!F6>=0.6041666666666666),"中抜",IF(AND(時間編集!C6<=0.5833333333333334,時間編集!D6>=0.6041666666666666),"●","")),"") | P6: =IF(AND(時間編集!C6<>"",時間編集!D6<>""),IF(AND(時間編集!E6<>"",時間編集!F6<>"",時間編集!E6<=0.6041666666666666,時間編集!F6>=0.625),"中抜",IF(AND(時間編集!C6<=0.6041666666666666,時間編集!D6>=0.625),"●","")),"") | Q6: =IF(AND(時間編集!C6<>"",時間編集!D6<>""),IF(AND(時間編集!E6<>"",時間編集!F6<>"",時間編集!E6<=0.625,時間編集!F6>=0.6458333333333334),"中抜",IF(AND(時間編集!C6<=0.625,時間編集!D6>=0.6458333333333334),"●","")),"") | R6: =IF(AND(時間編集!C6<>"",時間編集!D6<>""),IF(AND(時間編集!E6<>"",時間編集!F6<>"",時間編集!E6<=0.6458333333333334,時間編集!F6>=0.6666666666666666),"中抜",IF(AND(時間編集!C6<=0.6458333333333334,時間編集!D6>=0.6666666666666666),"●","")),"") | S6: =IF(AND(時間編集!C6<>"",時間編集!D6<>""),IF(AND(時間編集!E6<>"",時間編集!F6<>"",時間編集!E6<=0.6666666666666666,時間編集!F6>=0.6875),"中抜",IF(AND(時間編集!C6<=0.6666666666666666,時間編集!D6>=0.6875),"●","")),"") | T6: =IF(AND(時間編集!C6<>"",時間編集!D6<>""),IF(AND(時間編集!E6<>"",時間編集!F6<>"",時間編集!E6<=0.6875,時間編集!F6>=0.7083333333333334),"中抜",IF(AND(時間編集!C6<=0.6875,時間編集!D6>=0.7083333333333334),"●","")),"") | U6: =IF(AND(時間編集!C6<>"",時間編集!D6<>""),IF(AND(時間編集!E6<>"",時間編集!F6<>"",時間編集!E6<=0.7083333333333334,時間編集!F6>=0.7291666666666666),"中抜",IF(AND(時間編集!C6<=0.7083333333333334,時間編集!D6>=0.7291666666666666),"●","")),"") | V6: =IF(AND(時間編集!C6<>"",時間編集!D6<>""),IF(AND(時間編集!E6<>"",時間編集!F6<>"",時間編集!E6<=0.7291666666666666,時間編集!F6>=0.75),"中抜",IF(AND(時間編集!C6<=0.7291666666666666,時間編集!D6>=0.75),"●","")),"") | W6: =IF(AND(時間編集!C6<>"",時間編集!D6<>""),IF(AND(時間編集!E6<>"",時間編集!F6<>"",時間編集!E6<=0.75,時間編集!F6>=0.7708333333333334),"中抜",IF(AND(時間編集!C6<=0.75,時間編集!D6>=0.7708333333333334),"●","")),"") | X6: =IF(AND(時間編集!C6<>"",時間編集!D6<>""),IF(AND(時間編集!E6<>"",時間編集!F6<>"",時間編集!E6<=0.7708333333333334,時間編集!F6>=0.7916666666666666),"中抜",IF(AND(時間編集!C6<=0.7708333333333334,時間編集!D6>=0.7916666666666666),"●","")),"")
B7: 木 | C7: =IF(AND(時間編集!C7<>"",時間編集!D7<>""),IF(AND(時間編集!E7<>"",時間編集!F7<>"",時間編集!E7<=0.3333333333333333,時間編集!F7>=0.3541666666666667),"中抜",IF(AND(時間編集!C7<=0.3333333333333333,時間編集!D7>=0.3541666666666667),"●","")),"") | D7: =IF(AND(時間編集!C7<>"",時間編集!D7<>""),IF(AND(時間編集!E7<>"",時間編集!F7<>"",時間編集!E7<=0.3541666666666667,時間編集!F7>=0.375),"中抜",IF(AND(時間編集!C7<=0.3541666666666667,時間編集!D7>=0.375),"●","")),"") | E7: =IF(AND(時間編集!C7<>"",時間編集!D7<>""),IF(AND(時間編集!E7<>"",時間編集!F7<>"",時間編集!E7<=0.375,時間編集!F7>=0.3958333333333333),"中抜",IF(AND(時間編集!C7<=0.375,時間編集!D7>=0.3958333333333333),"●","")),"") | F7: =IF(AND(時間編集!C7<>"",時間編集!D7<>""),IF(AND(時間編集!E7<>"",時間編集!F7<>"",時間編集!E7<=0.3958333333333333,時間編集!F7>=0.4166666666666667),"中抜",IF(AND(時間編集!C7<=0.3958333333333333,時間編集!D7>=0.4166666666666667),"●","")),"") | G7: =IF(AND(時間編集!C7<>"",時間編集!D7<>""),IF(AND(時間編集!E7<>"",時間編集!F7<>"",時間編集!E7<=0.4166666666666667,時間編集!F7>=0.4375),"中抜",IF(AND(時間編集!C7<=0.4166666666666667,時間編集!D7>=0.4375),"●","")),"") | H7: =IF(AND(時間編集!C7<>"",時間編集!D7<>""),IF(AND(時間編集!E7<>"",時間編集!F7<>"",時間編集!E7<=0.4375,時間編集!F7>=0.4583333333333333),"中抜",IF(AND(時間編集!C7<=0.4375,時間編集!D7>=0.4583333333333333),"●","")),"") | I7: =IF(AND(時間編集!C7<>"",時間編集!D7<>""),IF(AND(時間編集!E7<>"",時間編集!F7<>"",時間編集!E7<=0.4583333333333333,時間編集!F7>=0.4791666666666667),"中抜",IF(AND(時間編集!C7<=0.4583333333333333,時間編集!D7>=0.4791666666666667),"●","")),"") | J7: =IF(AND(時間編集!C7<>"",時間編集!D7<>""),IF(AND(時間編集!E7<>"",時間編集!F7<>"",時間編集!E7<=0.4791666666666667,時間編集!F7>=0.5),"中抜",IF(AND(時間編集!C7<=0.4791666666666667,時間編集!D7>=0.5),"●","")),"") | K7: =IF(AND(時間編集!C7<>"",時間編集!D7<>""),IF(AND(時間編集!E7<>"",時間編集!F7<>"",時間編集!E7<=0.5,時間編集!F7>=0.5208333333333334),"中抜",IF(AND(時間編集!C7<=0.5,時間編集!D7>=0.5208333333333334),"●","")),"") | L7: =IF(AND(時間編集!C7<>"",時間編集!D7<>""),IF(AND(時間編集!E7<>"",時間編集!F7<>"",時間編集!E7<=0.5208333333333334,時間編集!F7>=0.5416666666666666),"中抜",IF(AND(時間編集!C7<=0.5208333333333334,時間編集!D7>=0.5416666666666666),"●","")),"") | M7: =IF(AND(時間編集!C7<>"",時間編集!D7<>""),IF(AND(時間編集!E7<>"",時間編集!F7<>"",時間編集!E7<=0.5416666666666666,時間編集!F7>=0.5625),"中抜",IF(AND(時間編集!C7<=0.5416666666666666,時間編集!D7>=0.5625),"●","")),"") | N7: =IF(AND(時間編集!C7<>"",時間編集!D7<>""),IF(AND(時間編集!E7<>"",時間編集!F7<>"",時間編集!E7<=0.5625,時間編集!F7>=0.5833333333333334),"中抜",IF(AND(時間編集!C7<=0.5625,時間編集!D7>=0.5833333333333334),"●","")),"") | O7: =IF(AND(時間編集!C7<>"",時間編集!D7<>""),IF(AND(時間編集!E7<>"",時間編集!F7<>"",時間編集!E7<=0.5833333333333334,時間編集!F7>=0.6041666666666666),"中抜",IF(AND(時間編集!C7<=0.5833333333333334,時間編集!D7>=0.6041666666666666),"●","")),"") | P7: =IF(AND(時間編集!C7<>"",時間編集!D7<>""),IF(AND(時間編集!E7<>"",時間編集!F7<>"",時間編集!E7<=0.6041666666666666,時間編集!F7>=0.625),"中抜",IF(AND(時間編集!C7<=0.6041666666666666,時間編集!D7>=0.625),"●","")),"") | Q7: =IF(AND(時間編集!C7<>"",時間編集!D7<>""),IF(AND(時間編集!E7<>"",時間編集!F7<>"",時間編集!E7<=0.625,時間編集!F7>=0.6458333333333334),"中抜",IF(AND(時間編集!C7<=0.625,時間編集!D7>=0.6458333333333334),"●","")),"") | R7: =IF(AND(時間編集!C7<>"",時間編集!D7<>""),IF(AND(時間編集!E7<>"",時間編集!F7<>"",時間編集!E7<=0.6458333333333334,時間編集!F7>=0.6666666666666666),"中抜",IF(AND(時間編集!C7<=0.6458333333333334,時間編集!D7>=0.6666666666666666),"●","")),"") | S7: =IF(AND(時間編集!C7<>"",時間編集!D7<>""),IF(AND(時間編集!E7<>"",時間編集!F7<>"",時間編集!E7<=0.6666666666666666,時間編集!F7>=0.6875),"中抜",IF(AND(時間編集!C7<=0.6666666666666666,時間編集!D7>=0.6875),"●","")),"") | T7: =IF(AND(時間編集!C7<>"",時間編集!D7<>""),IF(AND(時間編集!E7<>"",時間編集!F7<>"",時間編集!E7<=0.6875,時間編集!F7>=0.7083333333333334),"中抜",IF(AND(時間編集!C7<=0.6875,時間編集!D7>=0.7083333333333334),"●","")),"") | U7: =IF(AND(時間編集!C7<>"",時間編集!D7<>""),IF(AND(時間編集!E7<>"",時間編集!F7<>"",時間編集!E7<=0.7083333333333334,時間編集!F7>=0.7291666666666666),"中抜",IF(AND(時間編集!C7<=0.7083333333333334,時間編集!D7>=0.7291666666666666),"●","")),"") | V7: =IF(AND(時間編集!C7<>"",時間編集!D7<>""),IF(AND(時間編集!E7<>"",時間編集!F7<>"",時間編集!E7<=0.7291666666666666,時間編集!F7>=0.75),"中抜",IF(AND(時間編集!C7<=0.7291666666666666,時間編集!D7>=0.75),"●","")),"") | W7: =IF(AND(時間編集!C7<>"",時間編集!D7<>""),IF(AND(時間編集!E7<>"",時間編集!F7<>"",時間編集!E7<=0.75,時間編集!F7>=0.7708333333333334),"中抜",IF(AND(時間編集!C7<=0.75,時間編集!D7>=0.7708333333333334),"●","")),"") | X7: =IF(AND(時間編集!C7<>"",時間編集!D7<>""),IF(AND(時間編集!E7<>"",時間編集!F7<>"",時間編集!E7<=0.7708333333333334,時間編集!F7>=0.7916666666666666),"中抜",IF(AND(時間編集!C7<=0.7708333333333334,時間編集!D7>=0.7916666666666666),"●","")),"")
B8: 金 | C8: =IF(AND(時間編集!C8<>"",時間編集!D8<>""),IF(AND(時間編集!E8<>"",時間編集!F8<>"",時間編集!E8<=0.3333333333333333,時間編集!F8>=0.3541666666666667),"中抜",IF(AND(時間編集!C8<=0.3333333333333333,時間編集!D8>=0.3541666666666667),"●","")),"") | D8: =IF(AND(時間編集!C8<>"",時間編集!D8<>""),IF(AND(時間編集!E8<>"",時間編集!F8<>"",時間編集!E8<=0.3541666666666667,時間編集!F8>=0.375),"中抜",IF(AND(時間編集!C8<=0.3541666666666667,時間編集!D8>=0.375),"●","")),"") | E8: =IF(AND(時間編集!C8<>"",時間編集!D8<>""),IF(AND(時間編集!E8<>"",時間編集!F8<>"",時間編集!E8<=0.375,時間編集!F8>=0.3958333333333333),"中抜",IF(AND(時間編集!C8<=0.375,時間編集!D8>=0.3958333333333333),"●","")),"") | F8: =IF(AND(時間編集!C8<>"",時間編集!D8<>""),IF(AND(時間編集!E8<>"",時間編集!F8<>"",時間編集!E8<=0.3958333333333333,時間編集!F8>=0.4166666666666667),"中抜",IF(AND(時間編集!C8<=0.3958333333333333,時間編集!D8>=0.4166666666666667),"●","")),"") | G8: =IF(AND(時間編集!C8<>"",時間編集!D8<>""),IF(AND(時間編集!E8<>"",時間編集!F8<>"",時間編集!E8<=0.4166666666666667,時間編集!F8>=0.4375),"中抜",IF(AND(時間編集!C8<=0.4166666666666667,時間編集!D8>=0.4375),"●","")),"") | H8: =IF(AND(時間編集!C8<>"",時間編集!D8<>""),IF(AND(時間編集!E8<>"",時間編集!F8<>"",時間編集!E8<=0.4375,時間編集!F8>=0.4583333333333333),"中抜",IF(AND(時間編集!C8<=0.4375,時間編集!D8>=0.4583333333333333),"●","")),"") | I8: =IF(AND(時間編集!C8<>"",時間編集!D8<>""),IF(AND(時間編集!E8<>"",時間編集!F8<>"",時間編集!E8<=0.4583333333333333,時間編集!F8>=0.4791666666666667),"中抜",IF(AND(時間編集!C8<=0.4583333333333333,時間編集!D8>=0.4791666666666667),"●","")),"") | J8: =IF(AND(時間編集!C8<>"",時間編集!D8<>""),IF(AND(時間編集!E8<>"",時間編集!F8<>"",時間編集!E8<=0.4791666666666667,時間編集!F8>=0.5),"中抜",IF(AND(時間編集!C8<=0.4791666666666667,時間編集!D8>=0.5),"●","")),"") | K8: =IF(AND(時間編集!C8<>"",時間編集!D8<>""),IF(AND(時間編集!E8<>"",時間編集!F8<>"",時間編集!E8<=0.5,時間編集!F8>=0.5208333333333334),"中抜",IF(AND(時間編集!C8<=0.5,時間編集!D8>=0.5208333333333334),"●","")),"") | L8: =IF(AND(時間編集!C8<>"",時間編集!D8<>""),IF(AND(時間編集!E8<>"",時間編集!F8<>"",時間編集!E8<=0.5208333333333334,時間編集!F8>=0.5416666666666666),"中抜",IF(AND(時間編集!C8<=0.5208333333333334,時間編集!D8>=0.5416666666666666),"●","")),"") | M8: =IF(AND(時間編集!C8<>"",時間編集!D8<>""),IF(AND(時間編集!E8<>"",時間編集!F8<>"",時間編集!E8<=0.5416666666666666,時間編集!F8>=0.5625),"中抜",IF(AND(時間編集!C8<=0.5416666666666666,時間編集!D8>=0.5625),"●","")),"") | N8: =IF(AND(時間編集!C8<>"",時間編集!D8<>""),IF(AND(時間編集!E8<>"",時間編集!F8<>"",時間編集!E8<=0.5625,時間編集!F8>=0.5833333333333334),"中抜",IF(AND(時間編集!C8<=0.5625,時間編集!D8>=0.5833333333333334),"●","")),"") | O8: =IF(AND(時間編集!C8<>"",時間編集!D8<>""),IF(AND(時間編集!E8<>"",時間編集!F8<>"",時間編集!E8<=0.5833333333333334,時間編集!F8>=0.6041666666666666),"中抜",IF(AND(時間編集!C8<=0.5833333333333334,時間編集!D8>=0.6041666666666666),"●","")),"") | P8: =IF(AND(時間編集!C8<>"",時間編集!D8<>""),IF(AND(時間編集!E8<>"",時間編集!F8<>"",時間編集!E8<=0.6041666666666666,時間編集!F8>=0.625),"中抜",IF(AND(時間編集!C8<=0.6041666666666666,時間編集!D8>=0.625),"●","")),"") | Q8: =IF(AND(時間編集!C8<>"",時間編集!D8<>""),IF(AND(時間編集!E8<>"",時間編集!F8<>"",時間編集!E8<=0.625,時間編集!F8>=0.6458333333333334),"中抜",IF(AND(時間編集!C8<=0.625,時間編集!D8>=0.6458333333333334),"●","")),"") | R8: =IF(AND(時間編集!C8<>"",時間編集!D8<>""),IF(AND(時間編集!E8<>"",時間編集!F8<>"",時間編集!E8<=0.6458333333333334,時間編集!F8>=0.6666666666666666),"中抜",IF(AND(時間編集!C8<=0.6458333333333334,時間編集!D8>=0.6666666666666666),"●","")),"") | S8: =IF(AND(時間編集!C8<>"",時間編集!D8<>""),IF(AND(時間編集!E8<>"",時間編集!F8<>"",時間編集!E8<=0.6666666666666666,時間編集!F8>=0.6875),"中抜",IF(AND(時間編集!C8<=0.6666666666666666,時間編集!D8>=0.6875),"●","")),"") | T8: =IF(AND(時間編集!C8<>"",時間編集!D8<>""),IF(AND(時間編集!E8<>"",時間編集!F8<>"",時間編集!E8<=0.6875,時間編集!F8>=0.7083333333333334),"中抜",IF(AND(時間編集!C8<=0.6875,時間編集!D8>=0.7083333333333334),"●","")),"") | U8: =IF(AND(時間編集!C8<>"",時間編集!D8<>""),IF(AND(時間編集!E8<>"",時間編集!F8<>"",時間編集!E8<=0.7083333333333334,時間編集!F8>=0.7291666666666666),"中抜",IF(AND(時間編集!C8<=0.7083333333333334,時間編集!D8>=0.7291666666666666),"●","")),"") | V8: =IF(AND(時間編集!C8<>"",時間編集!D8<>""),IF(AND(時間編集!E8<>"",時間編集!F8<>"",時間編集!E8<=0.7291666666666666,時間編集!F8>=0.75),"中抜",IF(AND(時間編集!C8<=0.7291666666666666,時間編集!D8>=0.75),"●","")),"") | W8: =IF(AND(時間編集!C8<>"",時間編集!D8<>""),IF(AND(時間編集!E8<>"",時間編集!F8<>"",時間編集!E8<=0.75,時間編集!F8>=0.7708333333333334),"中抜",IF(AND(時間編集!C8<=0.75,時間編集!D8>=0.7708333333333334),"●","")),"") | X8: =IF(AND(時間編集!C8<>"",時間編集!D8<>""),IF(AND(時間編集!E8<>"",時間編集!F8<>"",時間編集!E8<=0.7708333333333334,時間編集!F8>=0.7916666666666666),"中抜",IF(AND(時間編集!C8<=0.7708333333333334,時間編集!D8>=0.7916666666666666),"●","")),"")
B9: 土 | C9: =IF(AND(時間編集!C9<>"",時間編集!D9<>""),IF(AND(時間編集!E9<>"",時間編集!F9<>"",時間編集!E9<=0.3333333333333333,時間編集!F9>=0.3541666666666667),"中抜",IF(AND(時間編集!C9<=0.3333333333333333,時間編集!D9>=0.3541666666666667),"●","")),"") | D9: =IF(AND(時間編集!C9<>"",時間編集!D9<>""),IF(AND(時間編集!E9<>"",時間編集!F9<>"",時間編集!E9<=0.3541666666666667,時間編集!F9>=0.375),"中抜",IF(AND(時間編集!C9<=0.3541666666666667,時間編集!D9>=0.375),"●","")),"") | E9: =IF(AND(時間編集!C9<>"",時間編集!D9<>""),IF(AND(時間編集!E9<>"",時間編集!F9<>"",時間編集!E9<=0.375,時間編集!F9>=0.3958333333333333),"中抜",IF(AND(時間編集!C9<=0.375,時間編集!D9>=0.3958333333333333),"●","")),"") | F9: =IF(AND(時間編集!C9<>"",時間編集!D9<>""),IF(AND(時間編集!E9<>"",時間編集!F9<>"",時間編集!E9<=0.3958333333333333,時間編集!F9>=0.4166666666666667),"中抜",IF(AND(時間編集!C9<=0.3958333333333333,時間編集!D9>=0.4166666666666667),"●","")),"") | G9: =IF(AND(時間編集!C9<>"",時間編集!D9<>""),IF(AND(時間編集!E9<>"",時間編集!F9<>"",時間編集!E9<=0.4166666666666667,時間編集!F9>=0.4375),"中抜",IF(AND(時間編集!C9<=0.4166666666666667,時間編集!D9>=0.4375),"●","")),"") | H9: =IF(AND(時間編集!C9<>"",時間編集!D9<>""),IF(AND(時間編集!E9<>"",時間編集!F9<>"",時間編集!E9<=0.4375,時間編集!F9>=0.4583333333333333),"中抜",IF(AND(時間編集!C9<=0.4375,時間編集!D9>=0.4583333333333333),"●","")),"") | I9: =IF(AND(時間編集!C9<>"",時間編集!D9<>""),IF(AND(時間編集!E9<>"",時間編集!F9<>"",時間編集!E9<=0.4583333333333333,時間編集!F9>=0.4791666666666667),"中抜",IF(AND(時間編集!C9<=0.4583333333333333,時間編集!D9>=0.4791666666666667),"●","")),"") | J9: =IF(AND(時間編集!C9<>"",時間編集!D9<>""),IF(AND(時間編集!E9<>"",時間編集!F9<>"",時間編集!E9<=0.4791666666666667,時間編集!F9>=0.5),"中抜",IF(AND(時間編集!C9<=0.4791666666666667,時間編集!D9>=0.5),"●","")),"") | K9: =IF(AND(時間編集!C9<>"",時間編集!D9<>""),IF(AND(時間編集!E9<>"",時間編集!F9<>"",時間編集!E9<=0.5,時間編集!F9>=0.5208333333333334),"中抜",IF(AND(時間編集!C9<=0.5,時間編集!D9>=0.5208333333333334),"●","")),"") | L9: =IF(AND(時間編集!C9<>"",時間編集!D9<>""),IF(AND(時間編集!E9<>"",時間編集!F9<>"",時間編集!E9<=0.5208333333333334,時間編集!F9>=0.5416666666666666),"中抜",IF(AND(時間編集!C9<=0.5208333333333334,時間編集!D9>=0.5416666666666666),"●","")),"") | M9: =IF(AND(時間編集!C9<>"",時間編集!D9<>""),IF(AND(時間編集!E9<>"",時間編集!F9<>"",時間編集!E9<=0.5416666666666666,時間編集!F9>=0.5625),"中抜",IF(AND(時間編集!C9<=0.5416666666666666,時間編集!D9>=0.5625),"●","")),"") | N9: =IF(AND(時間編集!C9<>"",時間編集!D9<>""),IF(AND(時間編集!E9<>"",時間編集!F9<>"",時間編集!E9<=0.5625,時間編集!F9>=0.5833333333333334),"中抜",IF(AND(時間編集!C9<=0.5625,時間編集!D9>=0.5833333333333334),"●","")),"") | O9: =IF(AND(時間編集!C9<>"",時間編集!D9<>""),IF(AND(時間編集!E9<>"",時間編集!F9<>"",時間編集!E9<=0.5833333333333334,時間編集!F9>=0.6041666666666666),"中抜",IF(AND(時間編集!C9<=0.5833333333333334,時間編集!D9>=0.6041666666666666),"●","")),"") | P9: =IF(AND(時間編集!C9<>"",時間編集!D9<>""),IF(AND(時間編集!E9<>"",時間編集!F9<>"",時間編集!E9<=0.6041666666666666,時間編集!F9>=0.625),"中抜",IF(AND(時間編集!C9<=0.6041666666666666,時間編集!D9>=0.625),"●","")),"") | Q9: =IF(AND(時間編集!C9<>"",時間編集!D9<>""),IF(AND(時間編集!E9<>"",時間編集!F9<>"",時間編集!E9<=0.625,時間編集!F9>=0.6458333333333334),"中抜",IF(AND(時間編集!C9<=0.625,時間編集!D9>=0.6458333333333334),"●","")),"") | R9: =IF(AND(時間編集!C9<>"",時間編集!D9<>""),IF(AND(時間編集!E9<>"",時間編集!F9<>"",時間編集!E9<=0.6458333333333334,時間編集!F9>=0.6666666666666666),"中抜",IF(AND(時間編集!C9<=0.6458333333333334,時間編集!D9>=0.6666666666666666),"●","")),"") | S9: =IF(AND(時間編集!C9<>"",時間編集!D9<>""),IF(AND(時間編集!E9<>"",時間編集!F9<>"",時間編集!E9<=0.6666666666666666,時間編集!F9>=0.6875),"中抜",IF(AND(時間編集!C9<=0.6666666666666666,時間編集!D9>=0.6875),"●","")),"") | T9: =IF(AND(時間編集!C9<>"",時間編集!D9<>""),IF(AND(時間編集!E9<>"",時間編集!F9<>"",時間編集!E9<=0.6875,時間編集!F9>=0.7083333333333334),"中抜",IF(AND(時間編集!C9<=0.6875,時間編集!D9>=0.7083333333333334),"●","")),"") | U9: =IF(AND(時間編集!C9<>"",時間編集!D9<>""),IF(AND(時間編集!E9<>"",時間編集!F9<>"",時間編集!E9<=0.7083333333333334,時間編集!F9>=0.7291666666666666),"中抜",IF(AND(時間編集!C9<=0.7083333333333334,時間編集!D9>=0.7291666666666666),"●","")),"") | V9: =IF(AND(時間編集!C9<>"",時間編集!D9<>""),IF(AND(時間編集!E9<>"",時間編集!F9<>"",時間編集!E9<=0.7291666666666666,時間編集!F9>=0.75),"中抜",IF(AND(時間編集!C9<=0.7291666666666666,時間編集!D9>=0.75),"●","")),"") | W9: =IF(AND(時間編集!C9<>"",時間編集!D9<>""),IF(AND(時間編集!E9<>"",時間編集!F9<>"",時間編集!E9<=0.75,時間編集!F9>=0.7708333333333334),"中抜",IF(AND(時間編集!C9<=0.75,時間編集!D9>=0.7708333333333334),"●","")),"") | X9: =IF(AND(時間編集!C9<>"",時間編集!D9<>""),IF(AND(時間編集!E9<>"",時間編集!F9<>"",時間編集!E9<=0.7708333333333334,時間編集!F9>=0.7916666666666666),"中抜",IF(AND(時間編集!C9<=0.7708333333333334,時間編集!D9>=0.7916666666666666),"●","")),"")
B10: 日 | C10: =IF(AND(時間編集!C10<>"",時間編集!D10<>""),IF(AND(時間編集!E10<>"",時間編集!F10<>"",時間編集!E10<=0.3333333333333333,時間編集!F10>=0.3541666666666667),"中抜",IF(AND(時間編集!C10<=0.3333333333333333,時間編集!D10>=0.3541666666666667),"●","")),"") | D10: =IF(AND(時間編集!C10<>"",時間編集!D10<>""),IF(AND(時間編集!E10<>"",時間編集!F10<>"",時間編集!E10<=0.3541666666666667,時間編集!F10>=0.375),"中抜",IF(AND(時間編集!C10<=0.3541666666666667,時間編集!D10>=0.375),"●","")),"") | E10: =IF(AND(時間編集!C10<>"",時間編集!D10<>""),IF(AND(時間編集!E10<>"",時間編集!F10<>"",時間編集!E10<=0.375,時間編集!F10>=0.3958333333333333),"中抜",IF(AND(時間編集!C10<=0.375,時間編集!D10>=0.3958333333333333),"●","")),"") | F10: =IF(AND(時間編集!C10<>"",時間編集!D10<>""),IF(AND(時間編集!E10<>"",時間編集!F10<>"",時間編集!E10<=0.3958333333333333,時間編集!F10>=0.4166666666666667),"中抜",IF(AND(時間編集!C10<=0.3958333333333333,時間編集!D10>=0.4166666666666667),"●","")),"") | G10: =IF(AND(時間編集!C10<>"",時間編集!D10<>""),IF(AND(時間編集!E10<>"",時間編集!F10<>"",時間編集!E10<=0.4166666666666667,時間編集!F10>=0.4375),"中抜",IF(AND(時間編集!C10<=0.4166666666666667,時間編集!D10>=0.4375),"●","")),"") | H10: =IF(AND(時間編集!C10<>"",時間編集!D10<>""),IF(AND(時間編集!E10<>"",時間編集!F10<>"",時間編集!E10<=0.4375,時間編集!F10>=0.4583333333333333),"中抜",IF(AND(時間編集!C10<=0.4375,時間編集!D10>=0.4583333333333333),"●","")),"") | I10: =IF(AND(時間編集!C10<>"",時間編集!D10<>""),IF(AND(時間編集!E10<>"",時間編集!F10<>"",時間編集!E10<=0.4583333333333333,時間編集!F10>=0.4791666666666667),"中抜",IF(AND(時間編集!C10<=0.4583333333333333,時間編集!D10>=0.4791666666666667),"●","")),"") | J10: =IF(AND(時間編集!C10<>"",時間編集!D10<>""),IF(AND(時間編集!E10<>"",時間編集!F10<>"",時間編集!E10<=0.4791666666666667,時間編集!F10>=0.5),"中抜",IF(AND(時間編集!C10<=0.4791666666666667,時間編集!D10>=0.5),"●","")),"") | K10: =IF(AND(時間編集!C10<>"",時間編集!D10<>""),IF(AND(時間編集!E10<>"",時間編集!F10<>"",時間編集!E10<=0.5,時間編集!F10>=0.5208333333333334),"中抜",IF(AND(時間編集!C10<=0.5,時間編集!D10>=0.5208333333333334),"●","")),"") | L10: =IF(AND(時間編集!C10<>"",時間編集!D10<>""),IF(AND(時間編集!E10<>"",時間編集!F10<>"",時間編集!E10<=0.5208333333333334,時間編集!F10>=0.5416666666666666),"中抜",IF(AND(時間編集!C10<=0.5208333333333334,時間編集!D10>=0.5416666666666666),"●","")),"") | M10: =IF(AND(時間編集!C10<>"",時間編集!D10<>""),IF(AND(時間編集!E10<>"",時間編集!F10<>"",時間編集!E10<=0.5416666666666666,時間編集!F10>=0.5625),"中抜",IF(AND(時間編集!C10<=0.5416666666666666,時間編集!D10>=0.5625),"●","")),"") | N10: =IF(AND(時間編集!C10<>"",時間編集!D10<>""),IF(AND(時間編集!E10<>"",時間編集!F10<>"",時間編集!E10<=0.5625,時間編集!F10>=0.5833333333333334),"中抜",IF(AND(時間編集!C10<=0.5625,時間編集!D10>=0.5833333333333334),"●","")),"") | O10: =IF(AND(時間編集!C10<>"",時間編集!D10<>""),IF(AND(時間編集!E10<>"",時間編集!F10<>"",時間編集!E10<=0.5833333333333334,時間編集!F10>=0.6041666666666666),"中抜",IF(AND(時間編集!C10<=0.5833333333333334,時間編集!D10>=0.6041666666666666),"●","")),"") | P10: =IF(AND(時間編集!C10<>"",時間編集!D10<>""),IF(AND(時間編集!E10<>"",時間編集!F10<>"",時間編集!E10<=0.6041666666666666,時間編集!F10>=0.625),"中抜",IF(AND(時間編集!C10<=0.6041666666666666,時間編集!D10>=0.625),"●","")),"") | Q10: =IF(AND(時間編集!C10<>"",時間編集!D10<>""),IF(AND(時間編集!E10<>"",時間編集!F10<>"",時間編集!E10<=0.625,時間編集!F10>=0.6458333333333334),"中抜",IF(AND(時間編集!C10<=0.625,時間編集!D10>=0.6458333333333334),"●","")),"") | R10: =IF(AND(時間編集!C10<>"",時間編集!D10<>""),IF(AND(時間編集!E10<>"",時間編集!F10<>"",時間編集!E10<=0.6458333333333334,時間編集!F10>=0.6666666666666666),"中抜",IF(AND(時間編集!C10<=0.6458333333333334,時間編集!D10>=0.6666666666666666),"●","")),"") | S10: =IF(AND(時間編集!C10<>"",時間編集!D10<>""),IF(AND(時間編集!E10<>"",時間編集!F10<>"",時間編集!E10<=0.6666666666666666,時間編集!F10>=0.6875),"中抜",IF(AND(時間編集!C10<=0.6666666666666666,時間編集!D10>=0.6875),"●","")),"") | T10: =IF(AND(時間編集!C10<>"",時間編集!D10<>""),IF(AND(時間編集!E10<>"",時間編集!F10<>"",時間編集!E10<=0.6875,時間編集!F10>=0.7083333333333334),"中抜",IF(AND(時間編集!C10<=0.6875,時間編集!D10>=0.7083333333333334),"●","")),"") | U10: =IF(AND(時間編集!C10<>"",時間編集!D10<>""),IF(AND(時間編集!E10<>"",時間編集!F10<>"",時間編集!E10<=0.7083333333333334,時間編集!F10>=0.7291666666666666),"中抜",IF(AND(時間編集!C10<=0.7083333333333334,時間編集!D10>=0.7291666666666666),"●","")),"") | V10: =IF(AND(時間編集!C10<>"",時間編集!D10<>""),IF(AND(時間編集!E10<>"",時間編集!F10<>"",時間編集!E10<=0.7291666666666666,時間編集!F10>=0.75),"中抜",IF(AND(時間編集!C10<=0.7291666666666666,時間編集!D10>=0.75),"●","")),"") | W10: =IF(AND(時間編集!C10<>"",時間編集!D10<>""),IF(AND(時間編集!E10<>"",時間編集!F10<>"",時間編集!E10<=0.75,時間編集!F10>=0.7708333333333334),"中抜",IF(AND(時間編集!C10<=0.75,時間編集!D10>=0.7708333333333334),"●","")),"") | X10: =IF(AND(時間編集!C10<>"",時間編集!D10<>""),IF(AND(時間編集!E10<>"",時間編集!F10<>"",時間編集!E10<=0.7708333333333334,時間編集!F10>=0.7916666666666666),"中抜",IF(AND(時間編集!C10<=0.7708333333333334,時間編集!D10>=0.7916666666666666),"●","")),"")
A11: 小泉 | B11: 月 | C11: =IF(AND(時間編集!C11<>"",時間編集!D11<>""),IF(AND(時間編集!E11<>"",時間編集!F11<>"",時間編集!E11<=0.3333333333333333,時間編集!F11>=0.3541666666666667),"中抜",IF(AND(時間編集!C11<=0.3333333333333333,時間編集!D11>=0.3541666666666667),"●","")),"") | D11: =IF(AND(時間編集!C11<>"",時間編集!D11<>""),IF(AND(時間編集!E11<>"",時間編集!F11<>"",時間編集!E11<=0.3541666666666667,時間編集!F11>=0.375),"中抜",IF(AND(時間編集!C11<=0.3541666666666667,時間編集!D11>=0.375),"●","")),"") | E11: =IF(AND(時間編集!C11<>"",時間編集!D11<>""),IF(AND(時間編集!E11<>"",時間編集!F11<>"",時間編集!E11<=0.375,時間編集!F11>=0.3958333333333333),"中抜",IF(AND(時間編集!C11<=0.375,時間編集!D11>=0.3958333333333333),"●","")),"") | F11: =IF(AND(時間編集!C11<>"",時間編集!D11<>""),IF(AND(時間編集!E11<>"",時間編集!F11<>"",時間編集!E11<=0.3958333333333333,時間編集!F11>=0.4166666666666667),"中抜",IF(AND(時間編集!C11<=0.3958333333333333,時間編集!D11>=0.4166666666666667),"●","")),"") | G11: =IF(AND(時間編集!C11<>"",時間編集!D11<>""),IF(AND(時間編集!E11<>"",時間編集!F11<>"",時間編集!E11<=0.4166666666666667,時間編集!F11>=0.4375),"中抜",IF(AND(時間編集!C11<=0.4166666666666667,時間編集!D11>=0.4375),"●","")),"") | H11: =IF(AND(時間編集!C11<>"",時間編集!D11<>""),IF(AND(時間編集!E11<>"",時間編集!F11<>"",時間編集!E11<=0.4375,時間編集!F11>=0.4583333333333333),"中抜",IF(AND(時間編集!C11<=0.4375,時間編集!D11>=0.4583333333333333),"●","")),"") | I11: =IF(AND(時間編集!C11<>"",時間編集!D11<>""),IF(AND(時間編集!E11<>"",時間編集!F11<>"",時間編集!E11<=0.4583333333333333,時間編集!F11>=0.4791666666666667),"中抜",IF(AND(時間編集!C11<=0.4583333333333333,時間編集!D11>=0.4791666666666667),"●","")),"") | J11: =IF(AND(時間編集!C11<>"",時間編集!D11<>""),IF(AND(時間編集!E11<>"",時間編集!F11<>"",時間編集!E11<=0.4791666666666667,時間編集!F11>=0.5),"中抜",IF(AND(時間編集!C11<=0.4791666666666667,時間編集!D11>=0.5),"●","")),"") | K11: =IF(AND(時間編集!C11<>"",時間編集!D11<>""),IF(AND(時間編集!E11<>"",時間編集!F11<>"",時間編集!E11<=0.5,時間編集!F11>=0.5208333333333334),"中抜",IF(AND(時間編集!C11<=0.5,時間編集!D11>=0.5208333333333334),"●","")),"") | L11: =IF(AND(時間編集!C11<>"",時間編集!D11<>""),IF(AND(時間編集!E11<>"",時間編集!F11<>"",時間編集!E11<=0.5208333333333334,時間編集!F11>=0.5416666666666666),"中抜",IF(AND(時間編集!C11<=0.5208333333333334,時間編集!D11>=0.5416666666666666),"●","")),"") | M11: =IF(AND(時間編集!C11<>"",時間編集!D11<>""),IF(AND(時間編集!E11<>"",時間編集!F11<>"",時間編集!E11<=0.5416666666666666,時間編集!F11>=0.5625),"中抜",IF(AND(時間編集!C11<=0.5416666666666666,時間編集!D11>=0.5625),"●","")),"") | N11: =IF(AND(時間編集!C11<>"",時間編集!D11<>""),IF(AND(時間編集!E11<>"",時間編集!F11<>"",時間編集!E11<=0.5625,時間編集!F11>=0.5833333333333334),"中抜",IF(AND(時間編集!C11<=0.5625,時間編集!D11>=0.5833333333333334),"●","")),"") | O11: =IF(AND(時間編集!C11<>"",時間編集!D11<>""),IF(AND(時間編集!E11<>"",時間編集!F11<>"",時間編集!E11<=0.5833333333333334,時間編集!F11>=0.6041666666666666),"中抜",IF(AND(時間編集!C11<=0.5833333333333334,時間編集!D11>=0.6041666666666666),"●","")),"") | P11: =IF(AND(時間編集!C11<>"",時間編集!D11<>""),IF(AND(時間編集!E11<>"",時間編集!F11<>"",時間編集!E11<=0.6041666666666666,時間編集!F11>=0.625),"中抜",IF(AND(時間編集!C11<=0.6041666666666666,時間編集!D11>=0.625),"●","")),"") | Q11: =IF(AND(時間編集!C11<>"",時間編集!D11<>""),IF(AND(時間編集!E11<>"",時間編集!F11<>"",時間編集!E11<=0.625,時間編集!F11>=0.6458333333333334),"中抜",IF(AND(時間編集!C11<=0.625,時間編集!D11>=0.6458333333333334),"●","")),"") | R11: =IF(AND(時間編集!C11<>"",時間編集!D11<>""),IF(AND(時間編集!E11<>"",時間編集!F11<>"",時間編集!E11<=0.6458333333333334,時間編集!F11>=0.6666666666666666),"中抜",IF(AND(時間編集!C11<=0.6458333333333334,時間編集!D11>=0.6666666666666666),"●","")),"") | S11: =IF(AND(時間編集!C11<>"",時間編集!D11<>""),IF(AND(時間編集!E11<>"",時間編集!F11<>"",時間編集!E11<=0.6666666666666666,時間編集!F11>=0.6875),"中抜",IF(AND(時間編集!C11<=0.6666666666666666,時間編集!D11>=0.6875),"●","")),"") | T11: =IF(AND(時間編集!C11<>"",時間編集!D11<>""),IF(AND(時間編集!E11<>"",時間編集!F11<>"",時間編集!E11<=0.6875,時間編集!F11>=0.7083333333333334),"中抜",IF(AND(時間編集!C11<=0.6875,時間編集!D11>=0.7083333333333334),"●","")),"") | U11: =IF(AND(時間編集!C11<>"",時間編集!D11<>""),IF(AND(時間編集!E11<>"",時間編集!F11<>"",時間編集!E11<=0.7083333333333334,時間編集!F11>=0.7291666666666666),"中抜",IF(AND(時間編集!C11<=0.7083333333333334,時間編集!D11>=0.7291666666666666),"●","")),"") | V11: =IF(AND(時間編集!C11<>"",時間編集!D11<>""),IF(AND(時間編集!E11<>"",時間編集!F11<>"",時間編集!E11<=0.7291666666666666,時間編集!F11>=0.75),"中抜",IF(AND(時間編集!C11<=0.7291666666666666,時間編集!D11>=0.75),"●","")),"") | W11: =IF(AND(時間編集!C11<>"",時間編集!D11<>""),IF(AND(時間編集!E11<>"",時間編集!F11<>"",時間編集!E11<=0.75,時間編集!F11>=0.7708333333333334),"中抜",IF(AND(時間編集!C11<=0.75,時間編集!D11>=0.7708333333333334),"●","")),"") | X11: =IF(AND(時間編集!C11<>"",時間編集!D11<>""),IF(AND(時間編集!E11<>"",時間編集!F11<>"",時間編集!E11<=0.7708333333333334,時間編集!F11>=0.7916666666666666),"中抜",IF(AND(時間編集!C11<=0.7708333333333334,時間編集!D11>=0.7916666666666666),"●","")),"")
B12: 火 | C12: =IF(AND(時間編集!C12<>"",時間編集!D12<>""),IF(AND(時間編集!E12<>"",時間編集!F12<>"",時間編集!E12<=0.3333333333333333,時間編集!F12>=0.3541666666666667),"中抜",IF(AND(時間編集!C12<=0.3333333333333333,時間編集!D12>=0.3541666666666667),"●","")),"") | D12: =IF(AND(時間編集!C12<>"",時間編集!D12<>""),IF(AND(時間編集!E12<>"",時間編集!F12<>"",時間編集!E12<=0.3541666666666667,時間編集!F12>=0.375),"中抜",IF(AND(時間編集!C12<=0.3541666666666667,時間編集!D12>=0.375),"●","")),"") | E12: =IF(AND(時間編集!C12<>"",時間編集!D12<>""),IF(AND(時間編集!E12<>"",時間編集!F12<>"",時間編集!E12<=0.375,時間編集!F12>=0.3958333333333333),"中抜",IF(AND(時間編集!C12<=0.375,時間編集!D12>=0.3958333333333333),"●","")),"") | F12: =IF(AND(時間編集!C12<>"",時間編集!D12<>""),IF(AND(時間編集!E12<>"",時間編集!F12<>"",時間編集!E12<=0.3958333333333333,時間編集!F12>=0.4166666666666667),"中抜",IF(AND(時間編集!C12<=0.3958333333333333,時間編集!D12>=0.4166666666666667),"●","")),"") | G12: =IF(AND(時間編集!C12<>"",時間編集!D12<>""),IF(AND(時間編集!E12<>"",時間編集!F12<>"",時間編集!E12<=0.4166666666666667,時間編集!F12>=0.4375),"中抜",IF(AND(時間編集!C12<=0.4166666666666667,時間編集!D12>=0.4375),"●","")),"") | H12: =IF(AND(時間編集!C12<>"",時間編集!D12<>""),IF(AND(時間編集!E12<>"",時間編集!F12<>"",時間編集!E12<=0.4375,時間編集!F12>=0.4583333333333333),"中抜",IF(AND(時間編集!C12<=0.4375,時間編集!D12>=0.4583333333333333),"●","")),"") | I12: =IF(AND(時間編集!C12<>"",時間編集!D12<>""),IF(AND(時間編集!E12<>"",時間編集!F12<>"",時間編集!E12<=0.4583333333333333,時間編集!F12>=0.4791666666666667),"中抜",IF(AND(時間編集!C12<=0.4583333333333333,時間編集!D12>=0.4791666666666667),"●","")),"") | J12: =IF(AND(時間編集!C12<>"",時間編集!D12<>""),IF(AND(時間編集!E12<>"",時間編集!F12<>"",時間編集!E12<=0.4791666666666667,時間編集!F12>=0.5),"中抜",IF(AND(時間編集!C12<=0.4791666666666667,時間編集!D12>=0.5),"●","")),"") | K12: =IF(AND(時間編集!C12<>"",時間編集!D12<>""),IF(AND(時間編集!E12<>"",時間編集!F12<>"",時間編集!E12<=0.5,時間編集!F12>=0.5208333333333334),"中抜",IF(AND(時間編集!C12<=0.5,時間編集!D12>=0.5208333333333334),"●","")),"") | L12: =IF(AND(時間編集!C12<>"",時間編集!D12<>""),IF(AND(時間編集!E12<>"",時間編集!F12<>"",時間編集!E12<=0.5208333333333334,時間編集!F12>=0.5416666666666666),"中抜",IF(AND(時間編集!C12<=0.5208333333333334,時間編集!D12>=0.5416666666666666),"●","")),"") | M12: =IF(AND(時間編集!C12<>"",時間編集!D12<>""),IF(AND(時間編集!E12<>"",時間編集!F12<>"",時間編集!E12<=0.5416666666666666,時間編集!F12>=0.5625),"中抜",IF(AND(時間編集!C12<=0.5416666666666666,時間編集!D12>=0.5625),"●","")),"") | N12: =IF(AND(時間編集!C12<>"",時間編集!D12<>""),IF(AND(時間編集!E12<>"",時間編集!F12<>"",時間編集!E12<=0.5625,時間編集!F12>=0.5833333333333334),"中抜",IF(AND(時間編集!C12<=0.5625,時間編集!D12>=0.5833333333333334),"●","")),"") | O12: =IF(AND(時間編集!C12<>"",時間編集!D12<>""),IF(AND(時間編集!E12<>"",時間編集!F12<>"",時間編集!E12<=0.5833333333333334,時間編集!F12>=0.6041666666666666),"中抜",IF(AND(時間編集!C12<=0.5833333333333334,時間編集!D12>=0.6041666666666666),"●","")),"") | P12: =IF(AND(時間編集!C12<>"",時間編集!D12<>""),IF(AND(時間編集!E12<>"",時間編集!F12<>"",時間編集!E12<=0.6041666666666666,時間編集!F12>=0.625),"中抜",IF(AND(時間編集!C12<=0.6041666666666666,時間編集!D12>=0.625),"●","")),"") | Q12: =IF(AND(時間編集!C12<>"",時間編集!D12<>""),IF(AND(時間編集!E12<>"",時間編集!F12<>"",時間編集!E12<=0.625,時間編集!F12>=0.6458333333333334),"中抜",IF(AND(時間編集!C12<=0.625,時間編集!D12>=0.6458333333333334),"●","")),"") | R12: =IF(AND(時間編集!C12<>"",時間編集!D12<>""),IF(AND(時間編集!E12<>"",時間編集!F12<>"",時間編集!E12<=0.6458333333333334,時間編集!F12>=0.6666666666666666),"中抜",IF(AND(時間編集!C12<=0.6458333333333334,時間編集!D12>=0.6666666666666666),"●","")),"") | S12: =IF(AND(時間編集!C12<>"",時間編集!D12<>""),IF(AND(時間編集!E12<>"",時間編集!F12<>"",時間編集!E12<=0.6666666666666666,時間編集!F12>=0.6875),"中抜",IF(AND(時間編集!C12<=0.6666666666666666,時間編集!D12>=0.6875),"●","")),"") | T12: =IF(AND(時間編集!C12<>"",時間編集!D12<>""),IF(AND(時間編集!E12<>"",時間編集!F12<>"",時間編集!E12<=0.6875,時間編集!F12>=0.7083333333333334),"中抜",IF(AND(時間編集!C12<=0.6875,時間編集!D12>=0.7083333333333334),"●","")),"") | U12: =IF(AND(時間編集!C12<>"",時間編集!D12<>""),IF(AND(時間編集!E12<>"",時間編集!F12<>"",時間編集!E12<=0.7083333333333334,時間編集!F12>=0.7291666666666666),"中抜",IF(AND(時間編集!C12<=0.7083333333333334,時間編集!D12>=0.7291666666666666),"●","")),"") | V12: =IF(AND(時間編集!C12<>"",時間編集!D12<>""),IF(AND(時間編集!E12<>"",時間編集!F12<>"",時間編集!E12<=0.7291666666666666,時間編集!F12>=0.75),"中抜",IF(AND(時間編集!C12<=0.7291666666666666,時間編集!D12>=0.75),"●","")),"") | W12: =IF(AND(時間編集!C12<>"",時間編集!D12<>""),IF(AND(時間編集!E12<>"",時間編集!F12<>"",時間編集!E12<=0.75,時間編集!F12>=0.7708333333333334),"中抜",IF(AND(時間編集!C12<=0.75,時間編集!D12>=0.7708333333333334),"●","")),"") | X12: =IF(AND(時間編集!C12<>"",時間編集!D12<>""),IF(AND(時間編集!E12<>"",時間編集!F12<>"",時間編集!E12<=0.7708333333333334,時間編集!F12>=0.7916666666666666),"中抜",IF(AND(時間編集!C12<=0.7708333333333334,時間編集!D12>=0.7916666666666666),"●","")),"")
B13: 水 | C13: =IF(AND(時間編集!C13<>"",時間編集!D13<>""),IF(AND(時間編集!E13<>"",時間編集!F13<>"",時間編集!E13<=0.3333333333333333,時間編集!F13>=0.3541666666666667),"中抜",IF(AND(時間編集!C13<=0.3333333333333333,時間編集!D13>=0.3541666666666667),"●","")),"") | D13: =IF(AND(時間編集!C13<>"",時間編集!D13<>""),IF(AND(時間編集!E13<>"",時間編集!F13<>"",時間編集!E13<=0.3541666666666667,時間編集!F13>=0.375),"中抜",IF(AND(時間編集!C13<=0.3541666666666667,時間編集!D13>=0.375),"●","")),"") | E13: =IF(AND(時間編集!C13<>"",時間編集!D13<>""),IF(AND(時間編集!E13<>"",時間編集!F13<>"",時間編集!E13<=0.375,時間編集!F13>=0.3958333333333333),"中抜",IF(AND(時間編集!C13<=0.375,時間編集!D13>=0.3958333333333333),"●","")),"") | F13: =IF(AND(時間編集!C13<>"",時間編集!D13<>""),IF(AND(時間編集!E13<>"",時間編集!F13<>"",時間編集!E13<=0.3958333333333333,時間編集!F13>=0.4166666666666667),"中抜",IF(AND(時間編集!C13<=0.3958333333333333,時間編集!D13>=0.4166666666666667),"●","")),"") | G13: =IF(AND(時間編集!C13<>"",時間編集!D13<>""),IF(AND(時間編集!E13<>"",時間編集!F13<>"",時間編集!E13<=0.4166666666666667,時間編集!F13>=0.4375),"中抜",IF(AND(時間編集!C13<=0.4166666666666667,時間編集!D13>=0.4375),"●","")),"") | H13: =IF(AND(時間編集!C13<>"",時間編集!D13<>""),IF(AND(時間編集!E13<>"",時間編集!F13<>"",時間編集!E13<=0.4375,時間編集!F13>=0.4583333333333333),"中抜",IF(AND(時間編集!C13<=0.4375,時間編集!D13>=0.4583333333333333),"●","")),"") | I13: =IF(AND(時間編集!C13<>"",時間編集!D13<>""),IF(AND(時間編集!E13<>"",時間編集!F13<>"",時間編集!E13<=0.4583333333333333,時間編集!F13>=0.4791666666666667),"中抜",IF(AND(時間編集!C13<=0.4583333333333333,時間編集!D13>=0.4791666666666667),"●","")),"") | J13: =IF(AND(時間編集!C13<>"",時間編集!D13<>""),IF(AND(時間編集!E13<>"",時間編集!F13<>"",時間編集!E13<=0.4791666666666667,時間編集!F13>=0.5),"中抜",IF(AND(時間編集!C13<=0.4791666666666667,時間編集!D13>=0.5),"●","")),"") | K13: =IF(AND(時間編集!C13<>"",時間編集!D13<>""),IF(AND(時間編集!E13<>"",時間編集!F13<>"",時間編集!E13<=0.5,時間編集!F13>=0.5208333333333334),"中抜",IF(AND(時間編集!C13<=0.5,時間編集!D13>=0.5208333333333334),"●","")),"") | L13: =IF(AND(時間編集!C13<>"",時間編集!D13<>""),IF(AND(時間編集!E13<>"",時間編集!F13<>"",時間編集!E13<=0.5208333333333334,時間編集!F13>=0.5416666666666666),"中抜",IF(AND(時間編集!C13<=0.5208333333333334,時間編集!D13>=0.5416666666666666),"●","")),"") | M13: =IF(AND(時間編集!C13<>"",時間編集!D13<>""),IF(AND(時間編集!E13<>"",時間編集!F13<>"",時間編集!E13<=0.5416666666666666,時間編集!F13>=0.5625),"中抜",IF(AND(時間編集!C13<=0.5416666666666666,時間編集!D13>=0.5625),"●","")),"") | N13: =IF(AND(時間編集!C13<>"",時間編集!D13<>""),IF(AND(時間編集!E13<>"",時間編集!F13<>"",時間編集!E13<=0.5625,時間編集!F13>=0.5833333333333334),"中抜",IF(AND(時間編集!C13<=0.5625,時間編集!D13>=0.5833333333333334),"●","")),"") | O13: =IF(AND(時間編集!C13<>"",時間編集!D13<>""),IF(AND(時間編集!E13<>"",時間編集!F13<>"",時間編集!E13<=0.5833333333333334,時間編集!F13>=0.6041666666666666),"中抜",IF(AND(時間編集!C13<=0.5833333333333334,時間編集!D13>=0.6041666666666666),"●","")),"") | P13: =IF(AND(時間編集!C13<>"",時間編集!D13<>""),IF(AND(時間編集!E13<>"",時間編集!F13<>"",時間編集!E13<=0.6041666666666666,時間編集!F13>=0.625),"中抜",IF(AND(時間編集!C13<=0.6041666666666666,時間編集!D13>=0.625),"●","")),"") | Q13: =IF(AND(時間編集!C13<>"",時間編集!D13<>""),IF(AND(時間編集!E13<>"",時間編集!F13<>"",時間編集!E13<=0.625,時間編集!F13>=0.6458333333333334),"中抜",IF(AND(時間編集!C13<=0.625,時間編集!D13>=0.6458333333333334),"●","")),"") | R13: =IF(AND(時間編集!C13<>"",時間編集!D13<>""),IF(AND(時間編集!E13<>"",時間編集!F13<>"",時間編集!E13<=0.6458333333333334,時間編集!F13>=0.6666666666666666),"中抜",IF(AND(時間編集!C13<=0.6458333333333334,時間編集!D13>=0.6666666666666666),"●","")),"") | S13: =IF(AND(時間編集!C13<>"",時間編集!D13<>""),IF(AND(時間編集!E13<>"",時間編集!F13<>"",時間編集!E13<=0.6666666666666666,時間編集!F13>=0.6875),"中抜",IF(AND(時間編集!C13<=0.6666666666666666,時間編集!D13>=0.6875),"●","")),"") | T13: =IF(AND(時間編集!C13<>"",時間編集!D13<>""),IF(AND(時間編集!E13<>"",時間編集!F13<>"",時間編集!E13<=0.6875,時間編集!F13>=0.7083333333333334),"中抜",IF(AND(時間編集!C13<=0.6875,時間編集!D13>=0.7083333333333334),"●","")),"") | U13: =IF(AND(時間編集!C13<>"",時間編集!D13<>""),IF(AND(時間編集!E13<>"",時間編集!F13<>"",時間編集!E13<=0.7083333333333334,時間編集!F13>=0.7291666666666666),"中抜",IF(AND(時間編集!C13<=0.7083333333333334,時間編集!D13>=0.7291666666666666),"●","")),"") | V13: =IF(AND(時間編集!C13<>"",時間編集!D13<>""),IF(AND(時間編集!E13<>"",時間編集!F13<>"",時間編集!E13<=0.7291666666666666,時間編集!F13>=0.75),"中抜",IF(AND(時間編集!C13<=0.7291666666666666,時間編集!D13>=0.75),"●","")),"") | W13: =IF(AND(時間編集!C13<>"",時間編集!D13<>""),IF(AND(時間編集!E13<>"",時間編集!F13<>"",時間編集!E13<=0.75,時間編集!F13>=0.7708333333333334),"中抜",IF(AND(時間編集!C13<=0.75,時間編集!D13>=0.7708333333333334),"●","")),"") | X13: =IF(AND(時間編集!C13<>"",時間編集!D13<>""),IF(AND(時間編集!E13<>"",時間編集!F13<>"",時間編集!E13<=0.7708333333333334,時間編集!F13>=0.7916666666666666),"中抜",IF(AND(時間編集!C13<=0.7708333333333334,時間編集!D13>=0.7916666666666666),"●","")),"")
B14: 木 | C14: =IF(AND(時間編集!C14<>"",時間編集!D14<>""),IF(AND(時間編集!E14<>"",時間編集!F14<>"",時間編集!E14<=0.3333333333333333,時間編集!F14>=0.3541666666666667),"中抜",IF(AND(時間編集!C14<=0.3333333333333333,時間編集!D14>=0.3541666666666667),"●","")),"") | D14: =IF(AND(時間編集!C14<>"",時間編集!D14<>""),IF(AND(時間編集!E14<>"",時間編集!F14<>"",時間編集!E14<=0.3541666666666667,時間編集!F14>=0.375),"中抜",IF(AND(時間編集!C14<=0.3541666666666667,時間編集!D14>=0.375),"●","")),"") | E14: =IF(AND(時間編集!C14<>"",時間編集!D14<>""),IF(AND(時間編集!E14<>"",時間編集!F14<>"",時間編集!E14<=0.375,時間編集!F14>=0.3958333333333333),"中抜",IF(AND(時間編集!C14<=0.375,時間編集!D14>=0.3958333333333333),"●","")),"") | F14: =IF(AND(時間編集!C14<>"",時間編集!D14<>""),IF(AND(時間編集!E14<>"",時間編集!F14<>"",時間編集!E14<=0.3958333333333333,時間編集!F14>=0.4166666666666667),"中抜",IF(AND(時間編集!C14<=0.3958333333333333,時間編集!D14>=0.4166666666666667),"●","")),"") | G14: =IF(AND(時間編集!C14<>"",時間編集!D14<>""),IF(AND(時間編集!E14<>"",時間編集!F14<>"",時間編集!E14<=0.4166666666666667,時間編集!F14>=0.4375),"中抜",IF(AND(時間編集!C14<=0.4166666666666667,時間編集!D14>=0.4375),"●","")),"") | H14: =IF(AND(時間編集!C14<>"",時間編集!D14<>""),IF(AND(時間編集!E14<>"",時間編集!F14<>"",時間編集!E14<=0.4375,時間編集!F14>=0.4583333333333333),"中抜",IF(AND(時間編集!C14<=0.4375,時間編集!D14>=0.4583333333333333),"●","")),"") | I14: =IF(AND(時間編集!C14<>"",時間編集!D14<>""),IF(AND(時間編集!E14<>"",時間編集!F14<>"",時間編集!E14<=0.4583333333333333,時間編集!F14>=0.4791666666666667),"中抜",IF(AND(時間編集!C14<=0.4583333333333333,時間編集!D14>=0.4791666666666667),"●","")),"") | J14: =IF(AND(時間編集!C14<>"",時間編集!D14<>""),IF(AND(時間編集!E14<>"",時間編集!F14<>"",時間編集!E14<=0.4791666666666667,時間編集!F14>=0.5),"中抜",IF(AND(時間編集!C14<=0.4791666666666667,時間編集!D14>=0.5),"●","")),"") | K14: =IF(AND(時間編集!C14<>"",時間編集!D14<>""),IF(AND(時間編集!E14<>"",時間編集!F14<>"",時間編集!E14<=0.5,時間編集!F14>=0.5208333333333334),"中抜",IF(AND(時間編集!C14<=0.5,時間編集!D14>=0.5208333333333334),"●","")),"") | L14: =IF(AND(時間編集!C14<>"",時間編集!D14<>""),IF(AND(時間編集!E14<>"",時間編集!F14<>"",時間編集!E14<=0.5208333333333334,時間編集!F14>=0.5416666666666666),"中抜",IF(AND(時間編集!C14<=0.5208333333333334,時間編集!D14>=0.5416666666666666),"●","")),"") | M14: =IF(AND(時間編集!C14<>"",時間編集!D14<>""),IF(AND(時間編集!E14<>"",時間編集!F14<>"",時間編集!E14<=0.5416666666666666,時間編集!F14>=0.5625),"中抜",IF(AND(時間編集!C14<=0.5416666666666666,時間編集!D14>=0.5625),"●","")),"") | N14: =IF(AND(時間編集!C14<>"",時間編集!D14<>""),IF(AND(時間編集!E14<>"",時間編集!F14<>"",時間編集!E14<=0.5625,時間編集!F14>=0.5833333333333334),"中抜",IF(AND(時間編集!C14<=0.5625,時間編集!D14>=0.5833333333333334),"●","")),"") | O14: =IF(AND(時間編集!C14<>"",時間編集!D14<>""),IF(AND(時間編集!E14<>"",時間編集!F14<>"",時間編集!E14<=0.5833333333333334,時間編集!F14>=0.6041666666666666),"中抜",IF(AND(時間編集!C14<=0.5833333333333334,時間編集!D14>=0.6041666666666666),"●","")),"") | P14: =IF(AND(時間編集!C14<>"",時間編集!D14<>""),IF(AND(時間編集!E14<>"",時間編集!F14<>"",時間編集!E14<=0.6041666666666666,時間編集!F14>=0.625),"中抜",IF(AND(時間編集!C14<=0.6041666666666666,時間編集!D14>=0.625),"●","")),"") | Q14: =IF(AND(時間編集!C14<>"",時間編集!D14<>""),IF(AND(時間編集!E14<>"",時間編集!F14<>"",時間編集!E14<=0.625,時間編集!F14>=0.6458333333333334),"中抜",IF(AND(時間編集!C14<=0.625,時間編集!D14>=0.6458333333333334),"●","")),"") | R14: =IF(AND(時間編集!C14<>"",時間編集!D14<>""),IF(AND(時間編集!E14<>"",時間編集!F14<>"",時間編集!E14<=0.6458333333333334,時間編集!F14>=0.6666666666666666),"中抜",IF(AND(時間編集!C14<=0.6458333333333334,時間編集!D14>=0.6666666666666666),"●","")),"") | S14: =IF(AND(時間編集!C14<>"",時間編集!D14<>""),IF(AND(時間編集!E14<>"",時間編集!F14<>"",時間編集!E14<=0.6666666666666666,時間編集!F14>=0.6875),"中抜",IF(AND(時間編集!C14<=0.6666666666666666,時間編集!D14>=0.6875),"●","")),"") | T14: =IF(AND(時間編集!C14<>"",時間編集!D14<>""),IF(AND(時間編集!E14<>"",時間編集!F14<>"",時間編集!E14<=0.6875,時間編集!F14>=0.7083333333333334),"中抜",IF(AND(時間編集!C14<=0.6875,時間編集!D14>=0.7083333333333334),"●","")),"") | U14: =IF(AND(時間編集!C14<>"",時間編集!D14<>""),IF(AND(時間編集!E14<>"",時間編集!F14<>"",時間編集!E14<=0.7083333333333334,時間編集!F14>=0.7291666666666666),"中抜",IF(AND(時間編集!C14<=0.7083333333333334,時間編集!D14>=0.7291666666666666),"●","")),"") | V14: =IF(AND(時間編集!C14<>"",時間編集!D14<>""),IF(AND(時間編集!E14<>"",時間編集!F14<>"",時間編集!E14<=0.7291666666666666,時間編集!F14>=0.75),"中抜",IF(AND(時間編集!C14<=0.7291666666666666,時間編集!D14>=0.75),"●","")),"") | W14: =IF(AND(時間編集!C14<>"",時間編集!D14<>""),IF(AND(時間編集!E14<>"",時間編集!F14<>"",時間編集!E14<=0.75,時間編集!F14>=0.7708333333333334),"中抜",IF(AND(時間編集!C14<=0.75,時間編集!D14>=0.7708333333333334),"●","")),"") | X14: =IF(AND(時間編集!C14<>"",時間編集!D14<>""),IF(AND(時間編集!E14<>"",時間編集!F14<>"",時間編集!E14<=0.7708333333333334,時間編集!F14>=0.7916666666666666),"中抜",IF(AND(時間編集!C14<=0.7708333333333334,時間編集!D14>=0.7916666666666666),"●","")),"")
B15: 金 | C15: =IF(AND(時間編集!C15<>"",時間編集!D15<>""),IF(AND(時間編集!E15<>"",時間編集!F15<>"",時間編集!E15<=0.3333333333333333,時間編集!F15>=0.3541666666666667),"中抜",IF(AND(時間編集!C15<=0.3333333333333333,時間編集!D15>=0.3541666666666667),"●","")),"") | D15: =IF(AND(時間編集!C15<>"",時間編集!D15<>""),IF(AND(時間編集!E15<>"",時間編集!F15<>"",時間編集!E15<=0.3541666666666667,時間編集!F15>=0.375),"中抜",IF(AND(時間編集!C15<=0.3541666666666667,時間編集!D15>=0.375),"●","")),"") | E15: =IF(AND(時間編集!C15<>"",時間編集!D15<>""),IF(AND(時間編集!E15<>"",時間編集!F15<>"",時間編集!E15<=0.375,時間編集!F15>=0.3958333333333333),"中抜",IF(AND(時間編集!C15<=0.375,時間編集!D15>=0.3958333333333333),"●","")),"") | F15: =IF(AND(時間編集!C15<>"",時間編集!D15<>""),IF(AND(時間編集!E15<>"",時間編集!F15<>"",時間編集!E15<=0.3958333333333333,時間編集!F15>=0.4166666666666667),"中抜",IF(AND(時間編集!C15<=0.3958333333333333,時間編集!D15>=0.4166666666666667),"●","")),"") | G15: =IF(AND(時間編集!C15<>"",時間編集!D15<>""),IF(AND(時間編集!E15<>"",時間編集!F15<>"",時間編集!E15<=0.4166666666666667,時間編集!F15>=0.4375),"中抜",IF(AND(時間編集!C15<=0.4166666666666667,時間編集!D15>=0.4375),"●","")),"") | H15: =IF(AND(時間編集!C15<>"",時間編集!D15<>""),IF(AND(時間編集!E15<>"",時間編集!F15<>"",時間編集!E15<=0.4375,時間編集!F15>=0.4583333333333333),"中抜",IF(AND(時間編集!C15<=0.4375,時間編集!D15>=0.4583333333333333),"●","")),"") | I15: =IF(AND(時間編集!C15<>"",時間編集!D15<>""),IF(AND(時間編集!E15<>"",時間編集!F15<>"",時間編集!E15<=0.4583333333333333,時間編集!F15>=0.4791666666666667),"中抜",IF(AND(時間編集!C15<=0.4583333333333333,時間編集!D15>=0.4791666666666667),"●","")),"") | J15: =IF(AND(時間編集!C15<>"",時間編集!D15<>""),IF(AND(時間編集!E15<>"",時間編集!F15<>"",時間編集!E15<=0.4791666666666667,時間編集!F15>=0.5),"中抜",IF(AND(時間編集!C15<=0.4791666666666667,時間編集!D15>=0.5),"●","")),"") | K15: =IF(AND(時間編集!C15<>"",時間編集!D15<>""),IF(AND(時間編集!E15<>"",時間編集!F15<>"",時間編集!E15<=0.5,時間編集!F15>=0.5208333333333334),"中抜",IF(AND(時間編集!C15<=0.5,時間編集!D15>=0.5208333333333334),"●","")),"") | L15: =IF(AND(時間編集!C15<>"",時間編集!D15<>""),IF(AND(時間編集!E15<>"",時間編集!F15<>"",時間編集!E15<=0.5208333333333334,時間編集!F15>=0.5416666666666666),"中抜",IF(AND(時間編集!C15<=0.5208333333333334,時間編集!D15>=0.5416666666666666),"●","")),"") | M15: =IF(AND(時間編集!C15<>"",時間編集!D15<>""),IF(AND(時間編集!E15<>"",時間編集!F15<>"",時間編集!E15<=0.5416666666666666,時間編集!F15>=0.5625),"中抜",IF(AND(時間編集!C15<=0.5416666666666666,時間編集!D15>=0.5625),"●","")),"") | N15: =IF(AND(時間編集!C15<>"",時間編集!D15<>""),IF(AND(時間編集!E15<>"",時間編集!F15<>"",時間編集!E15<=0.5625,時間編集!F15>=0.5833333333333334),"中抜",IF(AND(時間編集!C15<=0.5625,時間編集!D15>=0.5833333333333334),"●","")),"") | O15: =IF(AND(時間編集!C15<>"",時間編集!D15<>""),IF(AND(時間編集!E15<>"",時間編集!F15<>"",時間編集!E15<=0.5833333333333334,時間編集!F15>=0.6041666666666666),"中抜",IF(AND(時間編集!C15<=0.5833333333333334,時間編集!D15>=0.6041666666666666),"●","")),"") | P15: =IF(AND(時間編集!C15<>"",時間編集!D15<>""),IF(AND(時間編集!E15<>"",時間編集!F15<>"",時間編集!E15<=0.6041666666666666,時間編集!F15>=0.625),"中抜",IF(AND(時間編集!C15<=0.6041666666666666,時間編集!D15>=0.625),"●","")),"") | Q15: =IF(AND(時間編集!C15<>"",時間編集!D15<>""),IF(AND(時間編集!E15<>"",時間編集!F15<>"",時間編集!E15<=0.625,時間編集!F15>=0.6458333333333334),"中抜",IF(AND(時間編集!C15<=0.625,時間編集!D15>=0.6458333333333334),"●","")),"") | R15: =IF(AND(時間編集!C15<>"",時間編集!D15<>""),IF(AND(時間編集!E15<>"",時間編集!F15<>"",時間編集!E15<=0.6458333333333334,時間編集!F15>=0.6666666666666666),"中抜",IF(AND(時間編集!C15<=0.6458333333333334,時間編集!D15>=0.6666666666666666),"●","")),"") | S15: =IF(AND(時間編集!C15<>"",時間編集!D15<>""),IF(AND(時間編集!E15<>"",時間編集!F15<>"",時間編集!E15<=0.6666666666666666,時間編集!F15>=0.6875),"中抜",IF(AND(時間編集!C15<=0.6666666666666666,時間編集!D15>=0.6875),"●","")),"") | T15: =IF(AND(時間編集!C15<>"",時間編集!D15<>""),IF(AND(時間編集!E15<>"",時間編集!F15<>"",時間編集!E15<=0.6875,時間編集!F15>=0.7083333333333334),"中抜",IF(AND(時間編集!C15<=0.6875,時間編集!D15>=0.7083333333333334),"●","")),"") | U15: =IF(AND(時間編集!C15<>"",時間編集!D15<>""),IF(AND(時間編集!E15<>"",時間編集!F15<>"",時間編集!E15<=0.7083333333333334,時間編集!F15>=0.7291666666666666),"中抜",IF(AND(時間編集!C15<=0.7083333333333334,時間編集!D15>=0.7291666666666666),"●","")),"") | V15: =IF(AND(時間編集!C15<>"",時間編集!D15<>""),IF(AND(時間編集!E15<>"",時間編集!F15<>"",時間編集!E15<=0.7291666666666666,時間編集!F15>=0.75),"中抜",IF(AND(時間編集!C15<=0.7291666666666666,時間編集!D15>=0.75),"●","")),"") | W15: =IF(AND(時間編集!C15<>"",時間編集!D15<>""),IF(AND(時間編集!E15<>"",時間編集!F15<>"",時間編集!E15<=0.75,時間編集!F15>=0.7708333333333334),"中抜",IF(AND(時間編集!C15<=0.75,時間編集!D15>=0.7708333333333334),"●","")),"") | X15: =IF(AND(時間編集!C15<>"",時間編集!D15<>""),IF(AND(時間編集!E15<>"",時間編集!F15<>"",時間編集!E15<=0.7708333333333334,時間編集!F15>=0.7916666666666666),"中抜",IF(AND(時間編集!C15<=0.7708333333333334,時間編集!D15>=0.7916666666666666),"●","")),"")
B16: 土 | C16: =IF(AND(時間編集!C16<>"",時間編集!D16<>""),IF(AND(時間編集!E16<>"",時間編集!F16<>"",時間編集!E16<=0.3333333333333333,時間編集!F16>=0.3541666666666667),"中抜",IF(AND(時間編集!C16<=0.3333333333333333,時間編集!D16>=0.3541666666666667),"●","")),"") | D16: =IF(AND(時間編集!C16<>"",時間編集!D16<>""),IF(AND(時間編集!E16<>"",時間編集!F16<>"",時間編集!E16<=0.3541666666666667,時間編集!F16>=0.375),"中抜",IF(AND(時間編集!C16<=0.3541666666666667,時間編集!D16>=0.375),"●","")),"") | E16: =IF(AND(時間編集!C16<>"",時間編集!D16<>""),IF(AND(時間編集!E16<>"",時間編集!F16<>"",時間編集!E16<=0.375,時間編集!F16>=0.3958333333333333),"中抜",IF(AND(時間編集!C16<=0.375,時間編集!D16>=0.3958333333333333),"●","")),"") | F16: =IF(AND(時間編集!C16<>"",時間編集!D16<>""),IF(AND(時間編集!E16<>"",時間編集!F16<>"",時間編集!E16<=0.3958333333333333,時間編集!F16>=0.4166666666666667),"中抜",IF(AND(時間編集!C16<=0.3958333333333333,時間編集!D16>=0.4166666666666667),"●","")),"") | G16: =IF(AND(時間編集!C16<>"",時間編集!D16<>""),IF(AND(時間編集!E16<>"",時間編集!F16<>"",時間編集!E16<=0.4166666666666667,時間編集!F16>=0.4375),"中抜",IF(AND(時間編集!C16<=0.4166666666666667,時間編集!D16>=0.4375),"●","")),"") | H16: =IF(AND(時間編集!C16<>"",時間編集!D16<>""),IF(AND(時間編集!E16<>"",時間編集!F16<>"",時間編集!E16<=0.4375,時間編集!F16>=0.4583333333333333),"中抜",IF(AND(時間編集!C16<=0.4375,時間編集!D16>=0.4583333333333333),"●","")),"") | I16: =IF(AND(時間編集!C16<>"",時間編集!D16<>""),IF(AND(時間編集!E16<>"",時間編集!F16<>"",時間編集!E16<=0.4583333333333333,時間編集!F16>=0.4791666666666667),"中抜",IF(AND(時間編集!C16<=0.4583333333333333,時間編集!D16>=0.4791666666666667),"●","")),"") | J16: =IF(AND(時間編集!C16<>"",時間編集!D16<>""),IF(AND(時間編集!E16<>"",時間編集!F16<>"",時間編集!E16<=0.4791666666666667,時間編集!F16>=0.5),"中抜",IF(AND(時間編集!C16<=0.4791666666666667,時間編集!D16>=0.5),"●","")),"") | K16: =IF(AND(時間編集!C16<>"",時間編集!D16<>""),IF(AND(時間編集!E16<>"",時間編集!F16<>"",時間編集!E16<=0.5,時間編集!F16>=0.5208333333333334),"中抜",IF(AND(時間編集!C16<=0.5,時間編集!D16>=0.5208333333333334),"●","")),"") | L16: =IF(AND(時間編集!C16<>"",時間編集!D16<>""),IF(AND(時間編集!E16<>"",時間編集!F16<>"",時間編集!E16<=0.5208333333333334,時間編集!F16>=0.5416666666666666),"中抜",IF(AND(時間編集!C16<=0.5208333333333334,時間編集!D16>=0.5416666666666666),"●","")),"") | M16: =IF(AND(時間編集!C16<>"",時間編集!D16<>""),IF(AND(時間編集!E16<>"",時間編集!F16<>"",時間編集!E16<=0.5416666666666666,時間編集!F16>=0.5625),"中抜",IF(AND(時間編集!C16<=0.5416666666666666,時間編集!D16>=0.5625),"●","")),"") | N16: =IF(AND(時間編集!C16<>"",時間編集!D16<>""),IF(AND(時間編集!E16<>"",時間編集!F16<>"",時間編集!E16<=0.5625,時間編集!F16>=0.5833333333333334),"中抜",IF(AND(時間編集!C16<=0.5625,時間編集!D16>=0.5833333333333334),"●","")),"") | O16: =IF(AND(時間編集!C16<>"",時間編集!D16<>""),IF(AND(時間編集!E16<>"",時間編集!F16<>"",時間編集!E16<=0.5833333333333334,時間編集!F16>=0.6041666666666666),"中抜",IF(AND(時間編集!C16<=0.5833333333333334,時間編集!D16>=0.6041666666666666),"●","")),"") | P16: =IF(AND(時間編集!C16<>"",時間編集!D16<>""),IF(AND(時間編集!E16<>"",時間編集!F16<>"",時間編集!E16<=0.6041666666666666,時間編集!F16>=0.625),"中抜",IF(AND(時間編集!C16<=0.6041666666666666,時間編集!D16>=0.625),"●","")),"") | Q16: =IF(AND(時間編集!C16<>"",時間編集!D16<>""),IF(AND(時間編集!E16<>"",時間編集!F16<>"",時間編集!E16<=0.625,時間編集!F16>=0.6458333333333334),"中抜",IF(AND(時間編集!C16<=0.625,時間編集!D16>=0.6458333333333334),"●","")),"") | R16: =IF(AND(時間編集!C16<>"",時間編集!D16<>""),IF(AND(時間編集!E16<>"",時間編集!F16<>"",時間編集!E16<=0.6458333333333334,時間編集!F16>=0.6666666666666666),"中抜",IF(AND(時間編集!C16<=0.6458333333333334,時間編集!D16>=0.6666666666666666),"●","")),"") | S16: =IF(AND(時間編集!C16<>"",時間編集!D16<>""),IF(AND(時間編集!E16<>"",時間編集!F16<>"",時間編集!E16<=0.6666666666666666,時間編集!F16>=0.6875),"中抜",IF(AND(時間編集!C16<=0.6666666666666666,時間編集!D16>=0.6875),"●","")),"") | T16: =IF(AND(時間編集!C16<>"",時間編集!D16<>""),IF(AND(時間編集!E16<>"",時間編集!F16<>"",時間編集!E16<=0.6875,時間編集!F16>=0.7083333333333334),"中抜",IF(AND(時間編集!C16<=0.6875,時間編集!D16>=0.7083333333333334),"●","")),"") | U16: =IF(AND(時間編集!C16<>"",時間編集!D16<>""),IF(AND(時間編集!E16<>"",時間編集!F16<>"",時間編集!E16<=0.7083333333333334,時間編集!F16>=0.7291666666666666),"中抜",IF(AND(時間編集!C16<=0.7083333333333334,時間編集!D16>=0.7291666666666666),"●","")),"") | V16: =IF(AND(時間編集!C16<>"",時間編集!D16<>""),IF(AND(時間編集!E16<>"",時間編集!F16<>"",時間編集!E16<=0.7291666666666666,時間編集!F16>=0.75),"中抜",IF(AND(時間編集!C16<=0.7291666666666666,時間編集!D16>=0.75),"●","")),"") | W16: =IF(AND(時間編集!C16<>"",時間編集!D16<>""),IF(AND(時間編集!E16<>"",時間編集!F16<>"",時間編集!E16<=0.75,時間編集!F16>=0.7708333333333334),"中抜",IF(AND(時間編集!C16<=0.75,時間編集!D16>=0.7708333333333334),"●","")),"") | X16: =IF(AND(時間編集!C16<>"",時間編集!D16<>""),IF(AND(時間編集!E16<>"",時間編集!F16<>"",時間編集!E16<=0.7708333333333334,時間編集!F16>=0.7916666666666666),"中抜",IF(AND(時間編集!C16<=0.7708333333333334,時間編集!D16>=0.7916666666666666),"●","")),"")
